Workbook
Name 계획데이터: '3_1. 개발량 계획'!$A$2:$O$84
Name 실적데이터: '3_2. 개발량 실적'!$A$14:$O$95

Sheet 0. 사업계획
A1: ■ 전체 데이터 | F1: 값 입력
A3: 1. 2024년 실적
A4: 구 분 | C4: 1 | D4: 2 | E4: 3 | F4: 4 | G4: 5 | H4: 6 | I4: 7 | J4: 8 | K4: 9 | L4: 10 | M4: 11 | N4: 12 | O4: 연간계
A5: 공급전 | C5: 3144 | D5: 2356 | E5: 2424 | F5: 4160 | G5: 4095 | H5: 2928 | I5: 2187 | J5: 2466 | K5: 2412 | L5: 2443 | M5: 2935 | N5: 4016 | O5: =SUM(C5:N5) -> 35566
A6: 공급전 누계 | C6: =C5 -> 3144 | D6: =C6+D5 -> 5500 | E6: =D6+E5 -> 7924 | F6: =E6+F5 -> 12084 | G6: =F6+G5 -> 16179 | H6: =G6+H5 -> 19107 | I6: =H6+I5 -> 21294 | J6: =I6+J5 -> 23760 | K6: =J6+K5 -> 26172 | ... N6: =M6+N5 -> 35566 | O6: =N6 -> 35566
A7: 월 공급량(㎥) | C7: 168431283 | D7: 133092425 | E7: 120958338 | F7: 66900416 | G7: 56313203 | H7: 47949001 | I7: 48263208 | J7: 44234358 | K7: 42671369 | L7: 56594621 | M7: 90787759 | N7: 154556947 | O7: =SUM(C7:N7) -> 1030752928
A8: 공급량 누계(㎥) | C8: =C7 -> 168431283 | D8: =C8+D7 -> 301523708 | E8: =D8+E7 -> 422482046 | F8: =E8+F7 -> 489382462 | G8: =F8+G7 -> 545695665 | H8: =G8+H7 -> 593644666 | I8: =H8+I7 -> 641907874 | J8: =I8+J7 -> 686142232 | K8: =J8+K7 -> 728813601 | ... N8: =M8+N7 -> 1030752928 | O8: =N8 -> 1030752928
A9: 월 공급량(GJ) | C9: 7178986.7 | D9: 5704249 | E9: 5193238.2 | F9: 2859457.9 | G9: 2399133.1 | H9: 2034030 | I9: 2054228 | J9: 1881625.3 | K9: 1825384.2 | L9: 2408950.7 | M9: 3879263.7 | N9: 6619427.6 | O9: =SUM(C9:N9) -> 44037974
A10: 공급량 누계(GJ) | C10: =C9 -> 7178986.7 | D10: =C10+D9 -> 12883236 | E10: =D10+E9 -> 18076474 | F10: =E10+F9 -> 20935932 | G10: =F10+G9 -> 23335065 | H10: =G10+H9 -> 25369095 | I10: =H10+I9 -> 27423323 | J10: =I10+J9 -> 29304948 | K10: =J10+K9 -> 31130332 | ... N10: =M10+N9 -> 44037974 | O10: =N10 -> 44037974
C11: =ROUND(C9*1000,0) -> 7178986695 | D11: =ROUND(D9*1000,0) -> 5704248968 | E11: =ROUND(E9*1000,0) -> 5193238155 | F11: =ROUND(F9*1000,0) -> 2859457947 | G11: =ROUND(G9*1000,0) -> 2399133123 | H11: =ROUND(H9*1000,0) -> 2034030044 | I11: =ROUND(I9*1000,0) -> 2054227984 | J11: =ROUND(J9*1000,0) -> 1881625347 | ... N11: =ROUND(N9*1000,0) -> 6619427559 | O11: =SUM(C11:N11) -> 44037974407
A13: 2. 2025년 공급전 계획
A14: 구 분 | C14: 1 | D14: 2 | E14: 3 | F14: 4 | G14: 5 | H14: 6 | I14: 7 | J14: 8 | K14: 9 | L14: 10 | M14: 11 | N14: 12 | O14: 연간계 | P14: 검증
A15: normal | C15: 2893 | D15: 2174 | E15: 1562 | F15: 1172 | G15: 1423 | H15: 1541 | I15: 1406 | J15: 1661 | K15: 1846 | L15: 1495 | M15: 1497 | N15: 1624 | O15: 20294 | P15: =SUM(C15:N15) -> 20294 | R15: =O15=P15 -> TRUE
A16: 누 계 | C16: =C15 -> 2893 | D16: =C16+D15 -> 5067 | E16: =D16+E15 -> 6629 | F16: =E16+F15 -> 7801 | G16: =F16+G15 -> 9224 | H16: =G16+H15 -> 10765 | I16: =H16+I15 -> 12171 | J16: =I16+J15 -> 13832 | K16: =J16+K15 -> 15678 | ... N16: =M16+N15 -> 20294 | O16: =N16 -> 20294
A17: best | C17: 3040 | D17: 2263 | E17: 1608 | F17: 1204 | G17: 1492 | H17: 1583 | I17: 1444 | J17: 1690 | K17: 1864 | L17: 1524 | M17: 1535 | N17: 1748 | O17: 20995 | P17: =SUM(C17:N17) -> 20995 | R17: =O17=P17 -> TRUE
A18: 누 계 | C18: =C17 -> 3040 | D18: =C18+D17 -> 5303 | E18: =D18+E17 -> 6911 | F18: =E18+F17 -> 8115 | G18: =F18+G17 -> 9607 | H18: =G18+H17 -> 11190 | I18: =H18+I17 -> 12634 | J18: =I18+J17 -> 14324 | K18: =J18+K17 -> 16188 | ... N18: =M18+N17 -> 20995 | O18: =N18 -> 20995
A19: con. | C19: 2846 | D19: 2173 | E19: 1588 | F19: 1195 | G19: 1388 | H19: 1498 | I19: 1331 | J19: 1490 | K19: 1734 | L19: 1411 | M19: 1432 | N19: 1543 | O19: 19629 | P19: =SUM(C19:N19) -> 19629 | R19: =O19=P19 -> TRUE
A20: 누 계 | C20: =C19 -> 2846 | D20: =C20+D19 -> 5019 | E20: =D20+E19 -> 6607 | F20: =E20+F19 -> 7802 | G20: =F20+G19 -> 9190 | H20: =G20+H19 -> 10688 | I20: =H20+I19 -> 12019 | J20: =I20+J19 -> 13509 | K20: =J20+K19 -> 15243 | ... N20: =M20+N19 -> 19629 | O20: =N20 -> 19629
A23: 3. 2025년 공급량 계획 | D23: ▶ 2025년 열량값 | E23: 42.369
A24: 구 분 | C24: 1 | D24: 2 | E24: 3 | F24: 4 | G24: 5 | H24: 6 | I24: 7 | J24: 8 | K24: 9 | L24: 10 | M24: 11 | N24: 12 | O24: 연간계 | P24: 검증
A25: 월 공급량 (normal) | B25: ㎥ | P25: =SUM(C25:N25) -> 0 | R25: =O25=P25 -> TRUE
B26: 천㎥ | C26: =ROUND(C25/1000,0) -> 0 | D26: =ROUND(D25/1000,0) -> 0 | E26: =ROUND(E25/1000,0) -> 0 | F26: =ROUND(F25/1000,0) -> 0 | G26: =ROUND(G25/1000,0) -> 0 | H26: =ROUND(H25/1000,0) -> 0 | I26: =ROUND(I25/1000,0) -> 0 | J26: =ROUND(J25/1000,0) -> 0 | ... O26: =ROUND(O25/1000,0) -> 0 | P26: =ROUND(SUM(C26:N26),0) -> 0
B27: 누계 | C27: =C26 -> 0 | D27: =C27+D26 -> 0 | E27: =D27+E26 -> 0 | F27: =E27+F26 -> 0 | G27: =F27+G26 -> 0 | H27: =G27+H26 -> 0 | I27: =H27+I26 -> 0 | J27: =I27+J26 -> 0 | K27: =J27+K26 -> 0 | ... N27: =M27+N26 -> 0 | O27: =N27 -> 0
B28: MJ | C28: 7309529356 | D28: 5744742738 | E28: 4826077152 | F28: 3085078033 | G28: 2471083324 | H28: 2013875903 | I28: 2006152573 | J28: 1921945493 | K28: 2053319154 | L28: 2445221897 | M28: 4470414511 | N28: 7036986674 | O28: 45384426808 | P28: =SUM(C28:N28) -> 45384426808 | R28: =O28=P28 -> TRUE
B29: GJ | C29: =ROUND(C28/1000,0) -> 7309529 | D29: =ROUND(D28/1000,0) -> 5744743 | E29: =ROUND(E28/1000,0) -> 4826077 | F29: =ROUND(F28/1000,0) -> 3085078 | G29: =ROUND(G28/1000,0) -> 2471083 | H29: =ROUND(H28/1000,0) -> 2013876 | I29: =ROUND(I28/1000,0) -> 2006153 | J29: =ROUND(J28/1000,0) -> 1921945 | ... O29: =ROUND(O28/1000,0) -> 45384427 | P29: =SUM(C29:N29) -> 45384427
B30: TJ | C30: =C26*$E$23 -> 0 | D30: =D26*$E$23 -> 0 | E30: =E26*$E$23 -> 0 | F30: =F26*$E$23 -> 0 | G30: =G26*$E$23 -> 0 | H30: =H26*$E$23 -> 0 | I30: =I26*$E$23 -> 0 | J30: =J26*$E$23 -> 0 | ... O30: =O26*$E$23 -> 0 | P30: =ROUND(SUM(C30:N30),0) -> 0
B31: 누계 | C31: =C30 -> 0 | D31: =C31+D30 -> 0 | E31: =D31+E30 -> 0 | F31: =E31+F30 -> 0 | G31: =F31+G30 -> 0 | H31: =G31+H30 -> 0 | I31: =H31+I30 -> 0 | J31: =I31+J30 -> 0 | K31: =J31+K30 -> 0 | ... N31: =M31+N30 -> 0 | O31: =N31 -> 0
A32: 월 공급량 (best) | B32: ㎥ | P32: =SUM(C32:N32) -> 0 | R32: =O32=P32 -> TRUE
B33: 천㎥ | C33: =ROUND(C32/1000,0) -> 0 | D33: =ROUND(D32/1000,0) -> 0 | E33: =ROUND(E32/1000,0) -> 0 | F33: =ROUND(F32/1000,0) -> 0 | G33: =ROUND(G32/1000,0) -> 0 | H33: =ROUND(H32/1000,0) -> 0 | I33: =ROUND(I32/1000,0) -> 0 | J33: =ROUND(J32/1000,0) -> 0 | ... O33: =ROUND(O32/1000,0) -> 0 | P33: =ROUND(SUM(C33:N33),0) -> 0
B34: 누계 | C34: =C33 -> 0 | D34: =C34+D33 -> 0 | E34: =D34+E33 -> 0 | F34: =E34+F33 -> 0 | G34: =F34+G33 -> 0 | H34: =G34+H33 -> 0 | I34: =H34+I33 -> 0 | J34: =I34+J33 -> 0 | K34: =J34+K33 -> 0 | ... N34: =M34+N33 -> 0 | O34: =N34 -> 0
B35: MJ | C35: 7452949954 | D35: 5848989599 | E35: 4923676985 | F35: 3129143048 | G35: 2501464116 | H35: 2036266908 | I35: 2035683908 | J35: 1952402202 | K35: 2077236743 | L35: 2486005138 | M35: 4557272636 | N35: 7173645684 | O35: 46174736921 | P35: =SUM(C35:N35) -> 46174736921 | R35: =O35=P35 -> TRUE
B36: GJ | C36: =ROUND(C35/1000,0) -> 7452950 | D36: =ROUND(D35/1000,0) -> 5848990 | E36: =ROUND(E35/1000,0) -> 4923677 | F36: =ROUND(F35/1000,0) -> 3129143 | G36: =ROUND(G35/1000,0) -> 2501464 | H36: =ROUND(H35/1000,0) -> 2036267 | I36: =ROUND(I35/1000,0) -> 2035684 | J36: =ROUND(J35/1000,0) -> 1952402 | ... O36: =ROUND(O35/1000,0) -> 46174737 | P36: =SUM(C36:N36) -> 46174738
B37: TJ | C37: =C33*$E$23 -> 0 | D37: =D33*$E$23 -> 0 | E37: =E33*$E$23 -> 0 | F37: =F33*$E$23 -> 0 | G37: =G33*$E$23 -> 0 | H37: =H33*$E$23 -> 0 | I37: =I33*$E$23 -> 0 | J37: =J33*$E$23 -> 0 | ... O37: =O33*$E$23 -> 0 | P37: =ROUND(SUM(C37:N37),0) -> 0
B38: 누계 | C38: =C37 -> 0 | D38: =C38+D37 -> 0 | E38: =D38+E37 -> 0 | F38: =E38+F37 -> 0 | G38: =F38+G37 -> 0 | H38: =G38+H37 -> 0 | I38: =H38+I37 -> 0 | J38: =I38+J37 -> 0 | K38: =J38+K37 -> 0 | ... N38: =M38+N37 -> 0 | O38: =N38 -> 0
A39: 월 공급량 (con.) | B39: ㎥ | P39: =SUM(C39:N39) -> 0 | R39: =O39=P39 -> TRUE
B40: 천㎥ | C40: =ROUND(C39/1000,0) -> 0 | D40: =ROUND(D39/1000,0) -> 0 | E40: =ROUND(E39/1000,0) -> 0 | F40: =ROUND(F39/1000,0) -> 0 | G40: =ROUND(G39/1000,0) -> 0 | H40: =ROUND(H39/1000,0) -> 0 | I40: =ROUND(I39/1000,0) -> 0 | J40: =ROUND(J39/1000,0) -> 0 | ... O40: =ROUND(O39/1000,0) -> 0 | P40: =ROUND(SUM(C40:N40),0) -> 0
B41: 누계 | C41: =C40 -> 0 | D41: =C41+D40 -> 0 | E41: =D41+E40 -> 0 | F41: =E41+F40 -> 0 | G41: =F41+G40 -> 0 | H41: =G41+H40 -> 0 | I41: =H41+I40 -> 0 | J41: =I41+J40 -> 0 | K41: =J41+K40 -> 0 | ... N41: =M41+N40 -> 0 | O41: =N41 -> 0
B42: MJ | C42: 7044839530 | D42: 5536848216 | E42: 4663233183 | F42: 2995568879 | G42: 2410203382 | H42: 1972989199 | I42: 1964481820 | J42: 1879524330 | K42: 2003573234 | L42: 2367986414 | M42: 4313138811 | N42: 6763821500 | O42: 43916208498 | P42: =SUM(C42:N42) -> 43916208498 | R42: =O42=P42 -> TRUE
B43: GJ | C43: =ROUND(C42/1000,0) -> 7044840 | D43: =ROUND(D42/1000,0) -> 5536848 | E43: =ROUND(E42/1000,0) -> 4663233 | F43: =ROUND(F42/1000,0) -> 2995569 | G43: =ROUND(G42/1000,0) -> 2410203 | H43: =ROUND(H42/1000,0) -> 1972989 | I43: =ROUND(I42/1000,0) -> 1964482 | J43: =ROUND(J42/1000,0) -> 1879524 | ... O43: =ROUND(O42/1000,0) -> 43916208 | P43: =SUM(C43:N43) -> 43916208
B44: TJ | C44: =C40*$E$23 -> 0 | D44: =D40*$E$23 -> 0 | E44: =E40*$E$23 -> 0 | F44: =F40*$E$23 -> 0 | G44: =G40*$E$23 -> 0 | H44: =H40*$E$23 -> 0 | I44: =I40*$E$23 -> 0 | J44: =J40*$E$23 -> 0 | ... O44: =O40*$E$23 -> 0 | P44: =ROUND(SUM(C44:N44),0) -> 0
...

Sheet 1. 신규개발량_입력
A1: ■ 신규개발량 | E1: 45688 | K1: 2025년 열량값 | L1: 42.369 | N1: 값 입력
A3: 1. 공급전 | M3: - 당월 실적 입력(영업일보) | Q3: - 누계 실적
A4: 구 분 | C4: 전월 | F4: =MONTH($E$1)&"월" -> 1월 | I4: 당년 | K4: 총 누계 | M4: =MONTH($E$1)&"월" -> 1월 | Q4: 누계 전수
C5: 계획 | D5: 실적 | E5: 달성률 | F5: 계획 | G5: 실적 | H5: 달성률 | I5: 계획 | J5: 실적 | M5: 전월 실적 | N5: 당월 실적 | O5: 총 누계 | Q5: 전월까지 | R5: 당월까지 | S5: 연간 누계 | W5: 열병합용 | X5: 세너지 포함
A6: 공동주택 | C6: =IFERROR(HLOOKUP(MONTH($E$1),계획데이터,2,0),"") -> 2514 | D6: =M6 -> 0 | E6: =IFERROR(D6/C6,"") -> 0 | F6: =HLOOKUP(MONTH($E$1),계획데이터,2,0) -> 2514 | G6: =N6 -> 0 | H6: =IFERROR(G6/F6,"") -> 0 | I6: ='3_1. 개발량 계획'!O3 -> 16722 | J6: =Q6+N6 -> 0 | K6: =O6 -> 0 | R6: =G6+Q6 -> 0 | S6: ='3_2. 개발량 실적'!O15 -> 0 | T6: =EXACT(R6,S6) -> TRUE | W6: =O12 -> 0 | X6: =O12+6 -> 6
A7: 단독주택 | C7: =IFERROR(HLOOKUP(MONTH($E$1)-1,계획데이터,4,0),"") | D7: =M7 -> 0 | E7: =IFERROR(D7/C7,"") | F7: =HLOOKUP(MONTH($E$1),계획데이터,4,0) -> 281 | G7: =N7 -> 0 | H7: =IFERROR(G7/F7,"") -> 0 | I7: ='3_1. 개발량 계획'!O5 -> 2372 | J7: =Q7+N7 -> 0 | K7: =O7 -> 0 | R7: =G7+Q7 -> 0 | S7: ='3_2. 개발량 실적'!O17 -> 0 | T7: =EXACT(R7,S7) -> TRUE | W7: =SUM(O8:O11,W6) -> 0 | X7: =SUM(O8:O11,X6) -> 6
A8: 가정용 소계 | C8: =IFERROR(HLOOKUP(MONTH($E$1)-1,계획데이터,6,0),"") | D8: =M8 -> 0 | E8: =IFERROR(D8/C8,"") | F8: =HLOOKUP(MONTH($E$1),계획데이터,6,0) -> 2795 | G8: =N8 -> 0 | H8: =IFERROR(G8/F8,"") -> 0 | I8: ='3_1. 개발량 계획'!O7 -> 19094 | J8: =Q8+N8 -> 0 | K8: =O8 -> 0 | N8: =SUM(N6:N7) -> 0 | O8: =SUM(O6:O7) -> 0 | R8: =G8+Q8 -> 0 | S8: ='3_2. 개발량 실적'!O19 -> 0 | T8: =EXACT(R8,S8) -> TRUE | U8: =SUM(R6:R7) -> 0 | V8: =SUM(S6:S7) -> 0
A9: 일반용 | C9: =IFERROR(HLOOKUP(MONTH($E$1)-1,계획데이터,7,0),"") | D9: =M9 -> 0 | E9: =IFERROR(D9/C9,"") | F9: =HLOOKUP(MONTH($E$1),계획데이터,7,0) -> 66 | G9: =N9 -> 0 | H9: =IFERROR(G9/F9,"") -> 0 | I9: ='3_1. 개발량 계획'!O8 -> 868 | J9: =Q9+N9 -> 0 | K9: =O9 -> 0 | R9: =G9+Q9 -> 0 | S9: ='3_2. 개발량 실적'!O20 -> 0 | T9: =EXACT(R9,S9) -> TRUE
A10: 업무용 | C10: =IFERROR(HLOOKUP(MONTH($E$1)-1,계획데이터,9,0),"") | D10: =M10 -> 0 | E10: =IFERROR(D10/C10,"") | F10: =HLOOKUP(MONTH($E$1),계획데이터,9,0) -> 31 | G10: =N10 -> 0 | H10: =IFERROR(G10/F10,"") -> 0 | I10: ='3_1. 개발량 계획'!O10 -> 313 | J10: =Q10+N10 -> 0 | K10: =O10 -> 0 | R10: =G10+Q10 -> 0 | S10: ='3_2. 개발량 실적'!O22 -> 0 | T10: =EXACT(R10,S10) -> TRUE
A11: 산업용 | C11: =IFERROR(HLOOKUP(MONTH($E$1)-1,계획데이터,11,0),"") | D11: =M11 -> 0 | E11: =IFERROR(D11/C11,"") | F11: =HLOOKUP(MONTH($E$1),계획데이터,11,0) -> 1 | G11: =N11 -> 0 | H11: =IFERROR(G11/F11,"") -> 0 | I11: ='3_1. 개발량 계획'!O12 -> 12 | J11: =Q11+N11 -> 0 | K11: =O11 -> 0 | R11: =G11+Q11 -> 0 | S11: ='3_2. 개발량 실적'!O24 -> 0 | T11: =EXACT(R11,S11) -> TRUE
A12: 열병합 | C12: =IFERROR(HLOOKUP(MONTH($E$1)-1,계획데이터,13,0),"") | D12: =M12 -> 0 | E12: =IFERROR(D12/C12,"") | F12: =HLOOKUP(MONTH($E$1),계획데이터,13,0) -> 0 | G12: =N12 -> 0 | H12: =IFERROR(G12/F12,"") | I12: ='3_1. 개발량 계획'!O14 -> 7 | J12: =Q12+N12 -> 0 | K12: =O12 -> 0 | R12: =G12+Q12 -> 0 | S12: ='3_2. 개발량 실적'!O26 -> 0 | T12: =EXACT(R12,S12) -> TRUE
A13: 합 계 | C13: =IFERROR(HLOOKUP(MONTH($E$1)-1,계획데이터,15,0),"") | D13: =M13 -> 0 | E13: =IFERROR(D13/C13,"") | F13: =HLOOKUP(MONTH($E$1),계획데이터,15,0) -> 2893 | G13: =N13 -> 0 | H13: =IFERROR(G13/F13,"") -> 0 | I13: ='3_1. 개발량 계획'!O16 -> 20294 | J13: =Q13+N13 -> 0 | K13: =O13 -> 0 | N13: =SUM(N8:N12) -> 0 | O13: =SUM(O8:O12) -> 0 | R13: =G13+Q13 -> 0 | S13: ='3_2. 개발량 실적'!O28 -> 0 | T13: =EXACT(R13,S13) -> TRUE
C14: =C8=SUM(C6:C7) -> FALSE | D14: =D8=SUM(D6:D7) -> TRUE | F14: =F8=SUM(F6:F7) -> TRUE | G14: =G8=SUM(G6:G7) -> TRUE | I14: =I8=SUM(I6:I7) -> TRUE | J14: =J8=SUM(J6:J7) -> TRUE | K14: =K8=SUM(K6:K7) -> TRUE | M14: =M8=SUM(M6:M7) -> TRUE | N14: =N8=SUM(N6:N7) -> TRUE | O14: =O8=SUM(O6:O7) -> TRUE | Q14: =Q8=SUM(Q6:Q7) -> TRUE | R14: =R8=SUM(R6:R7) -> TRUE | S14: =S8=SUM(S6:S7) -> TRUE
C15: =C13=SUM(C8:C12) -> FALSE | D15: =D13=SUM(D8:D12) -> TRUE | F15: =F13=SUM(F8:F12) -> TRUE | G15: =G13=SUM(G8:G12) -> TRUE | I15: =I13=SUM(I8:I12) -> TRUE | J15: =J13=SUM(J8:J12) -> TRUE | K15: =K13=SUM(K8:K12) -> TRUE | M15: =M13=SUM(M8:M12) -> TRUE | N15: =N13=SUM(N8:N12) -> TRUE | O15: =O13=SUM(O8:O12) -> TRUE | Q15: =Q13=SUM(Q8:Q12) -> TRUE | R15: =R13=SUM(R8:R12) -> TRUE | S15: =S13=SUM(S8:S12) -> TRUE
M16: ① 당월 실적 → 전월 실적 값 복사 | Q16: ② 당월까지 누계 실적 → 전월까지 누계 실적 값 복사
A18: 2. 신규개발량(㎥) | C18: → 매년 초 전당사용량 변경할 것 (개발량 계획 sheet)
A19: 구 분 | C19: 전월 | F19: =MONTH($E$1)&"월" -> 1월 | I19: 연간 누계
C20: 계획 | D20: 실적 | E20: 달성률 | F20: 계획 | G20: 실적 | H20: 달성률 | I20: 계획 | J20: 추정 실적
A21: 공동주택 | C21: =IFERROR(HLOOKUP(MONTH($E$1)-1,계획데이터,20,0),"") | D21: =IFERROR(HLOOKUP(MONTH($E$1)-1,실적데이터,26,0),"") | E21: =IFERROR(D21/C21,"") | F21: =HLOOKUP(MONTH($E$1),계획데이터,20,0) -> 119164 | G21: =HLOOKUP(MONTH($E$1),실적데이터,26,0) -> 0 | H21: =IFERROR(G21/F21,"") -> 0 | I21: ='3_1. 개발량 계획'!O22 -> 5590728 | J21: ='3_2. 개발량 실적'!O40 -> 0
A22: 단독주택 | C22: =IFERROR(HLOOKUP(MONTH($E$1)-1,계획데이터,23,0),"") | D22: =IFERROR(HLOOKUP(MONTH($E$1)-1,실적데이터,29,0),"") | E22: =IFERROR(D22/C22,"") | F22: =HLOOKUP(MONTH($E$1),계획데이터,23,0) -> 11746 | G22: =HLOOKUP(MONTH($E$1),실적데이터,29,0) -> 0 | H22: =IFERROR(G22/F22,"") -> 0 | I22: ='3_1. 개발량 계획'!O25 -> 616215 | J22: ='3_2. 개발량 실적'!O43 -> 0
A23: 가정용 소계 | C23: =IFERROR(HLOOKUP(MONTH($E$1)-1,계획데이터,26,0),"") | D23: =IFERROR(HLOOKUP(MONTH($E$1)-1,실적데이터,32,0),"") | E23: =IFERROR(D23/C23,"") | F23: =HLOOKUP(MONTH($E$1),계획데이터,26,0) -> 130910 | G23: =HLOOKUP(MONTH($E$1),실적데이터,32,0) -> 0 | H23: =IFERROR(G23/F23,"") -> 0 | I23: ='3_1. 개발량 계획'!O28 -> 6206943 | J23: ='3_2. 개발량 실적'!O46 -> 0
A24: 일반용 | C24: =IFERROR(HLOOKUP(MONTH($E$1)-1,계획데이터,29,0),"") | D24: =IFERROR(HLOOKUP(MONTH($E$1)-1,실적데이터,35,0),"") | E24: =IFERROR(D24/C24,"") | F24: =HLOOKUP(MONTH($E$1),계획데이터,29,0) -> 13233 | G24: =HLOOKUP(MONTH($E$1),실적데이터,35,0) -> 0 | H24: =IFERROR(G24/F24,"") -> 0 | I24: ='3_1. 개발량 계획'!O31 -> 1072294 | J24: ='3_2. 개발량 실적'!O49 -> 0
A25: 업무용 | C25: =IFERROR(HLOOKUP(MONTH($E$1)-1,계획데이터,32,0),"") | D25: =IFERROR(HLOOKUP(MONTH($E$1)-1,실적데이터,38,0),"") | E25: =IFERROR(D25/C25,"") | F25: =HLOOKUP(MONTH($E$1),계획데이터,32,0) -> 12720 | G25: =HLOOKUP(MONTH($E$1),실적데이터,38,0) -> 0 | H25: =IFERROR(G25/F25,"") -> 0 | I25: ='3_1. 개발량 계획'!O34 -> 1145237 | J25: ='3_2. 개발량 실적'!O52 -> 0
A26: 산업용 | C26: =IFERROR(HLOOKUP(MONTH($E$1)-1,계획데이터,35,0),"") | D26: =IFERROR(HLOOKUP(MONTH($E$1)-1,실적데이터,41,0),"") | E26: =IFERROR(D26/C26,"") | F26: =HLOOKUP(MONTH($E$1),계획데이터,35,0) -> 5000 | G26: =HLOOKUP(MONTH($E$1),실적데이터,41,0) -> 0 | H26: =IFERROR(G26/F26,"") -> 0 | I26: ='3_1. 개발량 계획'!O37 -> 540000 | J26: ='3_2. 개발량 실적'!O55 -> 0
A27: 열병합 | C27: =IFERROR(HLOOKUP(MONTH($E$1)-1,계획데이터,38,0),"") | D27: =IFERROR(HLOOKUP(MONTH($E$1)-1,실적데이터,44,0),"") | E27: =IFERROR(D27/C27,"") | F27: =HLOOKUP(MONTH($E$1),계획데이터,38,0) -> 0 | G27: =HLOOKUP(MONTH($E$1),실적데이터,44,0) -> 0 | H27: =IFERROR(G27/F27,"") | I27: ='3_1. 개발량 계획'!O40 -> 0 | J27: ='3_2. 개발량 실적'!O58 -> 0
A28: 합 계(㎥) | C28: =IFERROR(HLOOKUP(MONTH($E$1)-1,계획데이터,44,0),"") | D28: =IFERROR(HLOOKUP(MONTH($E$1)-1,실적데이터,50,0),"") | E28: =IFERROR(D28/C28,"") | F28: =HLOOKUP(MONTH($E$1),계획데이터,44,0) -> 161863 | G28: =HLOOKUP(MONTH($E$1),실적데이터,50,0) -> 0 | H28: =IFERROR(G28/F28,"") -> 0 | I28: ='3_1. 개발량 계획'!O46 -> 8964474 | J28: ='3_2. 개발량 실적'!O64 -> 0
A29: 합 계(GJ) | C29: =IFERROR(HLOOKUP(MONTH($E$1)-1,계획데이터,81,0),"") | D29: =IFERROR(HLOOKUP(MONTH($E$1)-1,실적데이터,80,0),"") | E29: =IFERROR(D29/C29,"") | F29: =HLOOKUP(MONTH($E$1),계획데이터,81,0) -> 6857825 | G29: =HLOOKUP(MONTH($E$1),실적데이터,80,0) -> 0 | H29: =IFERROR(G29/F29,"") -> 0 | I29: ='3_1. 개발량 계획'!O83 -> 379801228 | J29: ='3_2. 개발량 실적'!O94 -> 0
C30: =C23=SUM(C21:C22) -> FALSE | D30: =D23=SUM(D21:D22) -> FALSE | F30: =F23=SUM(F21:F22) -> TRUE | G30: =G23=SUM(G21:G22) -> TRUE | I30: =I23=SUM(I21:I22) -> TRUE | J30: =J23=SUM(J21:J22) -> TRUE
C31: =C28=SUM(C23:C27) -> FALSE | D31: =D28=SUM(D23:D27) -> FALSE | F31: =F28=SUM(F23:F27) -> TRUE | G31: =G28=SUM(G23:G27) -> TRUE | I31: =I28=SUM(I23:I27) -> TRUE | J31: =J28=SUM(J23:J27) -> TRUE
C32: =IFERROR(C29/C28,"") | D32: =IFERROR(D29/D28,"") | F32: =F29/F28 -> 42.368083 | G32: =G29/G28 -> #DIV/0! | I32: =I29/I28 -> 42.367375 | J32: =J29/J28 -> #DIV/0!
A34: 3. 연간 공급량
A35: 구 분 | C35: 연간 | F35: =MONTH($E$1)&"월" -> 1월
C36: 계획 | D36: 실적 | E36: 달성률 | F36: 실적 | G36: 연간 달성률
A37: 부피(천㎥) | C37: 1117503 | E37: =D37/C37 -> 0 | G37: 0.8055
A38: 열량(GJ) | C38: 47722728 | E38: =D38/C38 -> 0
A41: 4. 업무용, 산업용 실적
A42: 구 분 | C42: 산업용 | F42: 업무용 | I42: 열병합
C43: 업체명 | D43: 전수 | E43: 사용량(㎥) | F43: 업체명 | G43: 전수 | H43: 사용량(㎥) | I43: 업체명 | J43: 전수 | K43: 사용량(㎥)
A44: 합 계 | D44: =SUM(D45:D53) -> 0 | E44: =ROUND(SUM(E45:E53),0) -> 0 | G44: =SUM(G45:G53) -> 0 | H44: =ROUND(SUM(H45:H53),0) -> 0 | J44: =SUM(J45:J53) -> 0 | K44: =ROUND(SUM(K45:K53),0) -> 0
A45: 산업에너지팀

Sheet 2. 월별 실적(2024년)
A1: ■ 실적(2025년) | F1: 값 입력
A3: 1. 공급전 실적
A4: 구 분 | C4: 상 반 기 | I4: 하 반 기 | O4: 연간계
C5: 1 | D5: 2 | E5: 3 | F5: 4 | G5: 5 | H5: 6 | I5: 7 | J5: 8 | K5: 9 | L5: 10 | M5: 11 | N5: 12
A6: 공동주택 | O6: =SUM(C6:N6) -> 0
A7: 단독주택 | O7: =SUM(C7:N7) -> 0
A8: 가정용 소계 | C8: =SUM(C6:C7) -> 0 | D8: =SUM(D6:D7) -> 0 | E8: =SUM(E6:E7) -> 0 | F8: =SUM(F6:F7) -> 0 | G8: =SUM(G6:G7) -> 0 | H8: =SUM(H6:H7) -> 0 | I8: =SUM(I6:I7) -> 0 | J8: =SUM(J6:J7) -> 0 | ... N8: =SUM(N6:N7) -> 0 | O8: =SUM(C8:N8) -> 0
A9: 일반용 | O9: =SUM(C9:N9) -> 0
A10: 업무용 | O10: =SUM(C10:N10) -> 0
A11: 산업용 | O11: =SUM(C11:N11) -> 0
A12: 열병합 | O12: =SUM(C12:N12) -> 0
A13: 합 계 | C13: =SUM(C8:C12) -> 0 | D13: =SUM(D8:D12) -> 0 | E13: =SUM(E8:E12) -> 0 | F13: =SUM(F8:F12) -> 0 | G13: =SUM(G8:G12) -> 0 | H13: =SUM(H8:H12) -> 0 | I13: =SUM(I8:I12) -> 0 | J13: =SUM(J8:J12) -> 0 | ... N13: =SUM(N8:N12) -> 0 | O13: =SUM(C13:N13) -> 0
A16: 2. 공급전 누계
A17: 구 분 | C17: 상 반 기 | H17: 하 반 기 | O17: 연간 누계
C18: 1 | D18: 2 | E18: 3 | F18: 4 | G18: 5 | H18: 6 | I18: 7 | J18: 8 | K18: 9 | L18: 10 | M18: 11 | N18: 12
A19: 공동주택 | C19: =C6 -> 0 | D19: =C19+D6 -> 0 | E19: =D19+E6 -> 0 | F19: =E19+F6 -> 0 | G19: =F19+G6 -> 0 | H19: =G19+H6 -> 0 | I19: =H19+I6 -> 0 | J19: =I19+J6 -> 0 | K19: =J19+K6 -> 0 | ... N19: =M19+N6 -> 0 | O19: =N19 -> 0
A20: 단독주택 | C20: =C7 -> 0 | D20: =C20+D7 -> 0 | E20: =D20+E7 -> 0 | F20: =E20+F7 -> 0 | G20: =F20+G7 -> 0 | H20: =G20+H7 -> 0 | I20: =H20+I7 -> 0 | J20: =I20+J7 -> 0 | K20: =J20+K7 -> 0 | ... N20: =M20+N7 -> 0 | O20: =N20 -> 0
A21: 가정용 소계 | C21: =C8 -> 0 | D21: =C21+D8 -> 0 | E21: =D21+E8 -> 0 | F21: =E21+F8 -> 0 | G21: =F21+G8 -> 0 | H21: =G21+H8 -> 0 | I21: =H21+I8 -> 0 | J21: =I21+J8 -> 0 | K21: =J21+K8 -> 0 | ... N21: =M21+N8 -> 0 | O21: =N21 -> 0
A22: 일반용 | C22: =C9 -> 0 | D22: =C22+D9 -> 0 | E22: =D22+E9 -> 0 | F22: =E22+F9 -> 0 | G22: =F22+G9 -> 0 | H22: =G22+H9 -> 0 | I22: =H22+I9 -> 0 | J22: =I22+J9 -> 0 | K22: =J22+K9 -> 0 | ... N22: =M22+N9 -> 0 | O22: =N22 -> 0
A23: 업무용 | C23: =C10 -> 0 | D23: =C23+D10 -> 0 | E23: =D23+E10 -> 0 | F23: =E23+F10 -> 0 | G23: =F23+G10 -> 0 | H23: =G23+H10 -> 0 | I23: =H23+I10 -> 0 | J23: =I23+J10 -> 0 | K23: =J23+K10 -> 0 | ... N23: =M23+N10 -> 0 | O23: =N23 -> 0
A24: 산업용 | C24: =C11 -> 0 | D24: =C24+D11 -> 0 | E24: =D24+E11 -> 0 | F24: =E24+F11 -> 0 | G24: =F24+G11 -> 0 | H24: =G24+H11 -> 0 | I24: =H24+I11 -> 0 | J24: =I24+J11 -> 0 | K24: =J24+K11 -> 0 | ... N24: =M24+N11 -> 0 | O24: =N24 -> 0
A25: 열병합 | C25: =C12 -> 0 | D25: =C25+D12 -> 0 | E25: =D25+E12 -> 0 | F25: =E25+F12 -> 0 | G25: =F25+G12 -> 0 | H25: =G25+H12 -> 0 | I25: =H25+I12 -> 0 | J25: =I25+J12 -> 0 | K25: =J25+K12 -> 0 | ... N25: =M25+N12 -> 0 | O25: =N25 -> 0
A26: 합 계 | C26: =C13 -> 0 | D26: =C26+D13 -> 0 | E26: =D26+E13 -> 0 | F26: =E26+F13 -> 0 | G26: =F26+G13 -> 0 | H26: =G26+H13 -> 0 | I26: =H26+I13 -> 0 | J26: =I26+J13 -> 0 | K26: =J26+K13 -> 0 | ... N26: =M26+N13 -> 0 | O26: =N26 -> 0
A29: 3. 공급량 실적 | E29: → [공급량 재산정] 파일 → 확정 공급량 값 입력
A30: 구 분 | C30: 상 반 기 | H30: 하 반 기 | O30: 연간 계
C31: 1 | D31: 2 | E31: 3 | F31: 4 | G31: 5 | H31: 6 | I31: 7 | J31: 8 | K31: 9 | L31: 10 | M31: 11 | N31: 12
A32: 가정용 | O32: =SUM(C32:N32) -> 0
A33: 일반용 | O33: =SUM(C33:N33) -> 0
A34: 업무용 | O34: =SUM(C34:N34) -> 0
A35: 산업용 | O35: =SUM(C35:N35) -> 0
A36: 열병합 | O36: =SUM(C36:N36) -> 0
A37: CNG | O37: =SUM(C37:N37) -> 0
A38: 합 계(㎥) | C38: =SUM(C32:C37) -> 0 | D38: =SUM(D32:D37) -> 0 | E38: =SUM(E32:E37) -> 0 | F38: =SUM(F32:F37) -> 0 | G38: =SUM(G32:G37) -> 0 | H38: =SUM(H32:H37) -> 0 | I38: =SUM(I32:I37) -> 0 | J38: =SUM(J32:J37) -> 0 | ... N38: =SUM(N32:N37) -> 0 | O38: =SUM(C38:N38) -> 0
A40: ▶ 공급량 확정값 입력(전체) | E40: → [공급량 일일보고서] 파일 → 총 공급량 | H40: ='0. 사업계획'!D23 -> ▶ 2025년 열량값 | I40: ='0. 사업계획'!E23 -> 42.369
A41: 부 피 | B41: (N㎥) | O41: =SUM(C41:N41) -> 0
B42: (천N㎥) | C42: =ROUND(C41/1000,1) -> 0 | D42: =ROUND(D41/1000,1) -> 0 | E42: =ROUND(E41/1000,1) -> 0 | F42: =ROUND(F41/1000,1) -> 0 | G42: =ROUND(G41/1000,1) -> 0 | H42: =ROUND(H41/1000,1) -> 0 | I42: =ROUND(I41/1000,1) -> 0 | J42: =ROUND(J41/1000,1) -> 0 | ... N42: =ROUND(N41/1000,1) -> 0
A43: 누 계(천N㎥) | C43: =C42 -> 0 | D43: =C43+D42 -> 0 | E43: =D43+E42 -> 0 | F43: =E43+F42 -> 0 | G43: =F43+G42 -> 0 | H43: =G43+H42 -> 0 | I43: =H43+I42 -> 0 | J43: =I43+J42 -> 0 | K43: =J43+K42 -> 0 | ... N43: =M43+N42 -> 0 | O43: =N43 -> 0
A44: 열량 | B44: GJ | O44: =SUM(C44:N44) -> 0
B45: TJ | C45: =ROUND(C44/1000,1) -> 0 | D45: =ROUND(D44/1000,1) -> 0 | E45: =ROUND(E44/1000,1) -> 0 | F45: =ROUND(F44/1000,1) -> 0 | G45: =ROUND(G44/1000,1) -> 0 | H45: =ROUND(H44/1000,1) -> 0 | I45: =ROUND(I44/1000,1) -> 0 | J45: =ROUND(J44/1000,1) -> 0 | ... N45: =ROUND(N44/1000,1) -> 0
A46: 누 계(TJ) | C46: =C45 -> 0 | D46: =C46+D45 -> 0 | E46: =D46+E45 -> 0 | F46: =E46+F45 -> 0 | G46: =F46+G45 -> 0 | H46: =G46+H45 -> 0 | I46: =H46+I45 -> 0 | J46: =I46+J45 -> 0 | K46: =J46+K45 -> 0 | ... N46: =M46+N45 -> 0 | O46: =N46 -> 0
...

Sheet 3_1. 개발량 계획
A1: 1. 공급전 계획 | N1: 2025년 열량값 | O1: 42.369 | R1: (250124) 3. 주택형태별 연간사용량 분석_작성_격월검침반영_확정
A2: 구분 | C2: 1 | D2: 2 | E2: 3 | F2: 4 | G2: 5 | H2: 6 | I2: 7 | J2: 8 | K2: 9 | L2: 10 | M2: 11 | N2: 12 | O2: 계 | P2: 1 | R2: 2025년 전당사용량
A3: 공동주택 | C3: 2514 | D3: 1896 | E3: 1311 | F3: 913 | G3: 1180 | H3: 1298 | I3: 1130 | J3: 1397 | K3: 1576 | L3: 1185 | M3: 1125 | N3: 1197 | O3: =SUM(C3:N3) -> 16722 | P3: 2
B4: (누계) | C4: =C3 -> 2514 | D4: =C4+D3 -> 4410 | E4: =D4+E3 -> 5721 | F4: =E4+F3 -> 6634 | G4: =F4+G3 -> 7814 | H4: =G4+H3 -> 9112 | I4: =H4+I3 -> 10242 | J4: =I4+J3 -> 11639 | K4: =J4+K3 -> 13215 | ... N4: =M4+N3 -> 16722 | P4: 3
A5: 단독주택 | C5: 281 | D5: 196 | E5: 153 | F5: 152 | G5: 145 | H5: 153 | I5: 179 | J5: 170 | K5: 185 | L5: 209 | M5: 245 | N5: 304 | O5: =SUM(C5:N5) -> 2372 | P5: 4
B6: (누계) | C6: =C5 -> 281 | D6: =C6+D5 -> 477 | E6: =D6+E5 -> 630 | F6: =E6+F5 -> 782 | G6: =F6+G5 -> 927 | H6: =G6+H5 -> 1080 | I6: =H6+I5 -> 1259 | J6: =I6+J5 -> 1429 | K6: =J6+K5 -> 1614 | ... N6: =M6+N5 -> 2372 | P6: 5
A7: 가정용 | C7: =C3+C5 -> 2795 | D7: =D3+D5 -> 2092 | E7: =E3+E5 -> 1464 | F7: =F3+F5 -> 1065 | G7: =G3+G5 -> 1325 | H7: =H3+H5 -> 1451 | I7: =I3+I5 -> 1309 | J7: =J3+J5 -> 1567 | ... N7: =N3+N5 -> 1501 | O7: =SUM(C7:N7) -> 19094 | P7: 6
A8: 일반용 | C8: 66 | D8: 57 | E8: 71 | F8: 72 | G8: 72 | H8: 67 | I8: 70 | J8: 65 | K8: 69 | L8: 77 | M8: 92 | N8: 90 | O8: =SUM(C8:N8) -> 868 | P8: 7
B9: (누계) | C9: =C8 -> 66 | D9: =C9+D8 -> 123 | E9: =D9+E8 -> 194 | F9: =E9+F8 -> 266 | G9: =F9+G8 -> 338 | H9: =G9+H8 -> 405 | I9: =H9+I8 -> 475 | J9: =I9+J8 -> 540 | K9: =J9+K8 -> 609 | ... N9: =M9+N8 -> 868 | P9: 8
A10: 업무용 | C10: 31 | D10: 24 | E10: 27 | F10: 33 | G10: 25 | H10: 22 | I10: 23 | J10: 27 | K10: 16 | L10: 23 | M10: 32 | N10: 30 | O10: =SUM(C10:N10) -> 313 | P10: 9
B11: (누계) | C11: =C10 -> 31 | D11: =C11+D10 -> 55 | E11: =D11+E10 -> 82 | F11: =E11+F10 -> 115 | G11: =F11+G10 -> 140 | H11: =G11+H10 -> 162 | I11: =H11+I10 -> 185 | J11: =I11+J10 -> 212 | K11: =J11+K10 -> 228 | ... N11: =M11+N10 -> 313 | P11: 10
A12: 산업용 | C12: 1 | D12: 1 | E12: 0 | F12: 1 | G12: 1 | H12: 1 | I12: 0 | J12: 1 | K12: 0 | L12: 1 | M12: 3 | N12: 2 | O12: =SUM(C12:N12) -> 12 | P12: 11
B13: (누계) | C13: =C12 -> 1 | D13: =C13+D12 -> 2 | E13: =D13+E12 -> 2 | F13: =E13+F12 -> 3 | G13: =F13+G12 -> 4 | H13: =G13+H12 -> 5 | I13: =H13+I12 -> 5 | J13: =I13+J12 -> 6 | K13: =J13+K12 -> 6 | ... N13: =M13+N12 -> 12 | P13: 12
A14: 열병합용 | C14: 0 | D14: 0 | E14: 0 | F14: 1 | G14: 0 | H14: 0 | I14: 4 | J14: 1 | K14: 0 | L14: 0 | M14: 0 | N14: 1 | O14: =SUM(C14:N14) -> 7 | P14: 13
B15: (누계) | C15: =C14 -> 0 | D15: =C15+D14 -> 0 | E15: =D15+E14 -> 0 | F15: =E15+F14 -> 1 | G15: =F15+G14 -> 1 | H15: =G15+H14 -> 1 | I15: =H15+I14 -> 5 | J15: =I15+J14 -> 6 | K15: =J15+K14 -> 6 | ... N15: =M15+N14 -> 7 | P15: 14
A16: 합 계 | C16: =SUM(C3,C5,C8,C10,C12,C14) -> 2893 | D16: =SUM(D3,D5,D8,D10,D12,D14) -> 2174 | E16: =SUM(E3,E5,E8,E10,E12,E14) -> 1562 | F16: =SUM(F3,F5,F8,F10,F12,F14) -> 1172 | G16: =SUM(G3,G5,G8,G10,G12,G14) -> 1423 | H16: =SUM(H3,H5,H8,H10,H12,H14) -> 1541 | I16: =SUM(I3,I5,I8,I10,I12,I14) -> 1406 | J16: =SUM(J3,J5,J8,J10,J12,J14) -> 1661 | ... N16: =SUM(N3,N5,N8,N10,N12,N14) -> 1624 | O16: =SUM(C16:N16) -> 20294 | P16: 15
B17: (누계) | C17: =C16 -> 2893 | D17: =C17+D16 -> 5067 | E17: =D17+E16 -> 6629 | F17: =E17+F16 -> 7801 | G17: =F17+G16 -> 9224 | H17: =G17+H16 -> 10765 | I17: =H17+I16 -> 12171 | J17: =I17+J16 -> 13832 | K17: =J17+K16 -> 15678 | ... N17: =M17+N16 -> 20294 | P17: 16
P18: 17
A19: 2. 신규개발량(㎥) | P19: 18
A20: 구분 | C20: 1 | D20: 2 | E20: 3 | F20: 4 | G20: 5 | H20: 6 | I20: 7 | J20: 8 | K20: 9 | L20: 10 | M20: 11 | N20: 12 | O20: 계 | P20: 19 | R20: 2025년 | S20: 2024년
A21: 공동주택 | C21: =ROUND(C3*$R$21,0) -> 119164 | D21: =ROUND(D3*$R$21,0) -> 89870 | E21: =ROUND(E3*$R$21,0) -> 62141 | F21: =ROUND(F3*$R$21,0) -> 43276 | G21: =ROUND(G3*$R$21,0) -> 55932 | H21: =ROUND(H3*$R$21,0) -> 61525 | I21: =ROUND(I3*$R$21,0) -> 53562 | J21: =ROUND(J3*$R$21,0) -> 66218 | ... N21: =ROUND(N3*$R$21,0) -> 56738 | O21: =SUM(C21:N21) -> 792622 | P21: 20 | Q21: 공동주택 | R21: 47.4 | S21: 50.42 | T21: =R21-S21 -> -3.02
B22: (누계) | C22: =C21 -> 119164 | D22: =C22+D21 -> 209034 | E22: =D22+E21 -> 271175 | F22: =E22+F21 -> 314451 | G22: =F22+G21 -> 370383 | H22: =G22+H21 -> 431908 | I22: =H22+I21 -> 485470 | J22: =I22+J21 -> 551688 | K22: =J22+K21 -> 626390 | ... N22: =M22+N21 -> 792622 | O22: =SUM(C22:N22) -> 5590728 | P22: 21
B23: (누적) | C23: =C22 -> 119164 | D23: =C23+D22 -> 328198 | E23: =D23+E22 -> 599373 | F23: =E23+F22 -> 913824 | G23: =F23+G22 -> 1284207 | H23: =G23+H22 -> 1716115 | I23: =H23+I22 -> 2201585 | J23: =I23+J22 -> 2753273 | K23: =J23+K22 -> 3379663 | ... N23: =M23+N22 -> 5590728 | O23: =EXACT(O22,N23) -> TRUE | P23: 22
A24: 단독주택 | C24: =ROUND(C5*$R$24,0) -> 11746 | D24: =ROUND(D5*$R$24,0) -> 8193 | E24: =ROUND(E5*$R$24,0) -> 6395 | F24: =ROUND(F5*$R$24,0) -> 6354 | G24: =ROUND(G5*$R$24,0) -> 6061 | H24: =ROUND(H5*$R$24,0) -> 6395 | I24: =ROUND(I5*$R$24,0) -> 7482 | J24: =ROUND(J5*$R$24,0) -> 7106 | ... N24: =ROUND(N5*$R$24,0) -> 12707 | O24: =SUM(C24:N24) -> 99149 | P24: 23 | Q24: 단독주택 | R24: 41.8 | S24: 44.11 | T24: =R24-S24 -> -2.31
B25: (누계) | C25: =C24 -> 11746 | D25: =C25+D24 -> 19939 | E25: =D25+E24 -> 26334 | F25: =E25+F24 -> 32688 | G25: =F25+G24 -> 38749 | H25: =G25+H24 -> 45144 | I25: =H25+I24 -> 52626 | J25: =I25+J24 -> 59732 | K25: =J25+K24 -> 67465 | ... N25: =M25+N24 -> 99149 | O25: =SUM(C25:N25) -> 616215 | P25: 24
B26: (누적) | C26: =C25 -> 11746 | D26: =C26+D25 -> 31685 | E26: =D26+E25 -> 58019 | F26: =E26+F25 -> 90707 | G26: =F26+G25 -> 129456 | H26: =G26+H25 -> 174600 | I26: =H26+I25 -> 227226 | J26: =I26+J25 -> 286958 | K26: =J26+K25 -> 354423 | ... N26: =M26+N25 -> 616215 | O26: =EXACT(O25,N26) -> TRUE | P26: 25
A27: 가정용 | C27: =C21+C24 -> 130910 | D27: =D21+D24 -> 98063 | E27: =E21+E24 -> 68536 | F27: =F21+F24 -> 49630 | G27: =G21+G24 -> 61993 | H27: =H21+H24 -> 67920 | I27: =I21+I24 -> 61044 | J27: =J21+J24 -> 73324 | ... N27: =N21+N24 -> 69445 | O27: =SUM(C27:N27) -> 891771 | P27: 26
B28: (누계) | C28: =C27 -> 130910 | D28: =C28+D27 -> 228973 | E28: =D28+E27 -> 297509 | F28: =E28+F27 -> 347139 | G28: =F28+G27 -> 409132 | H28: =G28+H27 -> 477052 | I28: =H28+I27 -> 538096 | J28: =I28+J27 -> 611420 | K28: =J28+K27 -> 693855 | ... N28: =M28+N27 -> 891771 | O28: =SUM(C28:N28) -> 6206943 | P28: 27
B29: (누적) | C29: =C28 -> 130910 | D29: =C29+D28 -> 359883 | E29: =D29+E28 -> 657392 | F29: =E29+F28 -> 1004531 | G29: =F29+G28 -> 1413663 | H29: =G29+H28 -> 1890715 | I29: =H29+I28 -> 2428811 | J29: =I29+J28 -> 3040231 | K29: =J29+K28 -> 3734086 | ... N29: =M29+N28 -> 6206943 | O29: =N29=(N23+N26) -> TRUE | P29: 28
A30: 일반용 | C30: =ROUND(C8*$R$30,0) -> 13233 | D30: =ROUND(D8*$R$30,0) -> 11429 | E30: =ROUND(E8*$R$30,0) -> 14236 | F30: =ROUND(F8*$R$30,0) -> 14436 | G30: =ROUND(G8*$R$30,0) -> 14436 | H30: =ROUND(H8*$R$30,0) -> 13434 | I30: =ROUND(I8*$R$30,0) -> 14035 | J30: =ROUND(J8*$R$30,0) -> 13033 | ... N30: =ROUND(N8*$R$30,0) -> 18045 | O30: =SUM(C30:N30) -> 174037 | P30: 29 | Q30: 일반용 | R30: 200.5 | S30: 118 | T30: =R30-S30 -> 82.5
B31: (누계) | C31: =C30 -> 13233 | D31: =C31+D30 -> 24662 | E31: =D31+E30 -> 38898 | F31: =E31+F30 -> 53334 | G31: =F31+G30 -> 67770 | H31: =G31+H30 -> 81204 | I31: =H31+I30 -> 95239 | J31: =I31+J30 -> 108272 | K31: =J31+K30 -> 122107 | ... N31: =M31+N30 -> 174037 | O31: =SUM(C31:N31) -> 1072294 | P31: 30
B32: (누적) | C32: =C31 -> 13233 | D32: =C32+D31 -> 37895 | E32: =D32+E31 -> 76793 | F32: =E32+F31 -> 130127 | G32: =F32+G31 -> 197897 | H32: =G32+H31 -> 279101 | I32: =H32+I31 -> 374340 | J32: =I32+J31 -> 482612 | K32: =J32+K31 -> 604719 | ... N32: =M32+N31 -> 1072294 | O32: =EXACT(O31,N32) -> TRUE | P32: 31
A33: 업무용 | C33: ='5. 업무용 판매량(2025년)'!D116 -> 12720 | D33: ='5. 업무용 판매량(2025년)'!E116 -> 14061 | E33: ='5. 업무용 판매량(2025년)'!F116 -> 14748 | F33: ='5. 업무용 판매량(2025년)'!G116 -> 18134 | G33: ='5. 업무용 판매량(2025년)'!H116 -> 15552 | H33: ='5. 업무용 판매량(2025년)'!I116 -> 9691 | I33: ='5. 업무용 판매량(2025년)'!J116 -> 13799 | J33: ='5. 업무용 판매량(2025년)'!K116 -> 20789 | ... N33: ='5. 업무용 판매량(2025년)'!O116 -> 20189 | O33: =SUM(C33:N33) -> 183397 | P33: 32
B34: (누계) | C34: =C33 -> 12720 | D34: =C34+D33 -> 26781 | E34: =D34+E33 -> 41529 | F34: =E34+F33 -> 59663 | G34: =F34+G33 -> 75215 | H34: =G34+H33 -> 84906 | I34: =H34+I33 -> 98705 | J34: =I34+J33 -> 119494 | K34: =J34+K33 -> 130804 | ... N34: =M34+N33 -> 183397 | O34: =SUM(C34:N34) -> 1145237 | P34: 33
B35: (누적) | C35: =C34 -> 12720 | D35: =C35+D34 -> 39501 | E35: =D35+E34 -> 81030 | F35: =E35+F34 -> 140693 | G35: =F35+G34 -> 215908 | H35: =G35+H34 -> 300814 | I35: =H35+I34 -> 399519 | J35: =I35+J34 -> 519013 | K35: =J35+K34 -> 649817 | ... N35: =M35+N34 -> 1145237 | O35: =EXACT(O34,N35) -> TRUE | P35: 34
A36: 산업용 | C36: ='4_5. 산업용 판매량(2025년)'!E46 -> 5000 | D36: ='4_5. 산업용 판매량(2025년)'!F46 -> 20000 | E36: ='4_5. 산업용 판매량(2025년)'!G46 -> 0 | F36: ='4_5. 산업용 판매량(2025년)'!H46 -> 5000 | G36: ='4_5. 산업용 판매량(2025년)'!I46 -> 5000 | H36: ='4_5. 산업용 판매량(2025년)'!J46 -> 5000 | I36: ='4_5. 산업용 판매량(2025년)'!K46 -> 0 | J36: ='4_5. 산업용 판매량(2025년)'!L46 -> 5000 | ... N36: ='4_5. 산업용 판매량(2025년)'!P46 -> 10000 | O36: =SUM(C36:N36) -> 105000 | P36: 35
B37: (누계) | C37: =C36 -> 5000 | D37: =C37+D36 -> 25000 | E37: =D37+E36 -> 25000 | F37: =E37+F36 -> 30000 | G37: =F37+G36 -> 35000 | H37: =G37+H36 -> 40000 | I37: =H37+I36 -> 40000 | J37: =I37+J36 -> 45000 | K37: =J37+K36 -> 45000 | ... N37: =M37+N36 -> 105000 | O37: =SUM(C37:N37) -> 540000 | P37: 36
B38: (누적) | C38: =C37 -> 5000 | D38: =C38+D37 -> 30000 | E38: =D38+E37 -> 55000 | F38: =E38+F37 -> 85000 | G38: =F38+G37 -> 120000 | H38: =G38+H37 -> 160000 | I38: =H38+I37 -> 200000 | J38: =I38+J37 -> 245000 | K38: =J38+K37 -> 290000 | ... N38: =M38+N37 -> 540000 | O38: =EXACT(O37,N38) -> TRUE | P38: 37
A39: 열병합용 | C39: 0 | D39: 0 | E39: 0 | F39: 0 | G39: 0 | H39: 0 | I39: 0 | J39: 0 | K39: 0 | L39: 0 | M39: 0 | N39: 0 | O39: =SUM(C39:N39) -> 0 | P39: 38
B40: (누계) | C40: =C39 -> 0 | D40: =C40+D39 -> 0 | E40: =D40+E39 -> 0 | F40: =E40+F39 -> 0 | G40: =F40+G39 -> 0 | H40: =G40+H39 -> 0 | I40: =H40+I39 -> 0 | J40: =I40+J39 -> 0 | K40: =J40+K39 -> 0 | ... N40: =M40+N39 -> 0 | O40: =SUM(C40:N40) -> 0 | P40: 39
...

Sheet 3_2. 개발량 실적
A1: 0. 요약 | C1: 1 | N1: 2025년 열량값 | O1: 42.369 | R1: (250124) 3. 주택형태별 연간사용량 분석_작성_격월검침반영_확정
A2: 열량(GJ) | B2: 계획 | C2: 실적 | D2: 달성률 | F2: 부피(㎥) | G2: 계획 | H2: 실적 | I2: 달성률
A3: 공동주택 | B3: ='3_1. 개발량 계획'!Q60 -> 236874 | C3: =ROUND(HLOOKUP($C$1,$A$68:$O$95,4,0)/1000,0) -> 0 | D3: =C3/B3 -> 0 | F3: 공동주택 | G3: ='3_1. 개발량 계획'!O22 -> 5590728 | H3: =HLOOKUP($C$1,$A$38:$O$65,4,0) -> 0 | I3: =H3/G3 -> 0
A4: 단독주택 | B4: ='3_1. 개발량 계획'!Q63 -> 26108 | C4: =ROUND(HLOOKUP($C$1,$A$68:$O$95,7,0)/1000,0) -> 0 | D4: =C4/B4 -> 0 | F4: 단독주택 | G4: ='3_1. 개발량 계획'!O25 -> 616215 | H4: =HLOOKUP($C$1,$A$38:$O$65,7,0) -> 0 | I4: =H4/G4 -> 0
A5: 가정용 | B5: =SUM(B3:B4) -> 262982 | C5: =SUM(C3:C4) -> 0 | D5: =C5/B5 -> 0 | F5: 가정용 | G5: =SUM(G3:G4) -> 6206943 | H5: =SUM(H3:H4) -> 0 | I5: =H5/G5 -> 0
A6: 일반용 | B6: ='3_1. 개발량 계획'!Q69 -> 45432 | C6: =ROUND(HLOOKUP($C$1,$A$68:$O$95,13,0)/1000,0) -> 0 | D6: =C6/B6 -> 0 | F6: 일반용 | G6: ='3_1. 개발량 계획'!O31 -> 1072294 | H6: =HLOOKUP($C$1,$A$38:$O$65,13,0) -> 0 | I6: =H6/G6 -> 0
A7: 업무용 | B7: ='3_1. 개발량 계획'!Q72 -> 48523 | C7: =ROUND(HLOOKUP($C$1,$A$68:$O$95,16,0)/1000,0) -> 0 | D7: =C7/B7 -> 0 | F7: 업무용 | G7: ='3_1. 개발량 계획'!O34 -> 1145237 | H7: =HLOOKUP($C$1,$A$38:$O$65,16,0) -> 0 | I7: =H7/G7 -> 0
A8: 산업용 | B8: ='3_1. 개발량 계획'!Q75 -> 22865 | C8: =ROUND(HLOOKUP($C$1,$A$68:$O$95,19,0)/1000,0) -> 0 | D8: =C8/B8 -> 0 | F8: 산업용 | G8: ='3_1. 개발량 계획'!O37 -> 540000 | H8: =HLOOKUP($C$1,$A$38:$O$65,19,0) -> 0 | I8: =H8/G8 -> 0
A9: 합계(CNG 제외) | B9: =SUM(B5:B8) -> 379802 | C9: =SUM(C5:C8) -> 0 | D9: =C9/B9 -> 0 | F9: 합계(CNG 제외) | G9: =SUM(G5:G8) -> 8964474 | H9: =SUM(H5:H8) -> 0 | I9: =H9/G9 -> 0
A10: CNG | B10: =ROUND('3_1. 개발량 계획'!Q98/1000,0) -> 0 | C10: =ROUND(HLOOKUP($C$1,$A$68:$O$95,25,0)/1000,0) -> 0 | D10: =C10/B10 -> #DIV/0! | F10: CNG | G10: =ROUND('3_1. 개발량 계획'!Q95,0) -> 0 | H10: =HLOOKUP($C$1,$A$38:$O$65,25,0) -> 0 | I10: =H10/G10 -> #DIV/0!
A11: 합계(CNG 포함) | B11: =SUM(B9:B10) -> 379802 | C11: =SUM(C9:C10) -> 0 | D11: =C11/B11 -> 0 | F11: 합계(CNG 포함) | G11: =SUM(G9:G10) -> 8964474 | H11: =SUM(H9:H10) -> 0 | I11: =H11/G11 -> 0
A13: 1. 공급전 실적
A14: 구분 | C14: 1 | D14: 2 | E14: 3 | F14: 4 | G14: 5 | H14: 6 | I14: 7 | J14: 8 | K14: 9 | L14: 10 | M14: 11 | N14: 12 | O14: 계 | P14: 1 | R14: 2025년 전당사용량
A15: 공동주택 | O15: =SUM(C15:N15) -> 0 | P15: 2
B16: (누계) | C16: =C15 -> 0 | D16: =C16+D15 -> 0 | E16: =D16+E15 -> 0 | F16: =E16+F15 -> 0 | G16: =F16+G15 -> 0 | H16: =G16+H15 -> 0 | I16: =H16+I15 -> 0 | J16: =I16+J15 -> 0 | K16: =J16+K15 -> 0 | ... N16: =M16+N15 -> 0 | P16: 3
A17: 단독주택 | O17: =SUM(C17:N17) -> 0 | P17: 4
B18: (누계) | C18: =C17 -> 0 | D18: =C18+D17 -> 0 | E18: =D18+E17 -> 0 | F18: =E18+F17 -> 0 | G18: =F18+G17 -> 0 | H18: =G18+H17 -> 0 | I18: =H18+I17 -> 0 | J18: =I18+J17 -> 0 | K18: =J18+K17 -> 0 | ... N18: =M18+N17 -> 0 | P18: 5
A19: 가정용 | C19: =C15+C17 -> 0 | D19: =D15+D17 -> 0 | E19: =E15+E17 -> 0 | F19: =F15+F17 -> 0 | G19: =G15+G17 -> 0 | H19: =H15+H17 -> 0 | I19: =I15+I17 -> 0 | J19: =J15+J17 -> 0 | ... N19: =N15+N17 -> 0 | O19: =SUM(C19:N19) -> 0 | P19: 6
A20: 일반용 | O20: =SUM(C20:N20) -> 0 | P20: 7
B21: (누계) | C21: =C20 -> 0 | D21: =C21+D20 -> 0 | E21: =D21+E20 -> 0 | F21: =E21+F20 -> 0 | G21: =F21+G20 -> 0 | H21: =G21+H20 -> 0 | I21: =H21+I20 -> 0 | J21: =I21+J20 -> 0 | K21: =J21+K20 -> 0 | ... N21: =M21+N20 -> 0 | P21: 8
A22: 업무용 | O22: =SUM(C22:N22) -> 0 | P22: 9
B23: (누계) | C23: =C22 -> 0 | D23: =C23+D22 -> 0 | E23: =D23+E22 -> 0 | F23: =E23+F22 -> 0 | G23: =F23+G22 -> 0 | H23: =G23+H22 -> 0 | I23: =H23+I22 -> 0 | J23: =I23+J22 -> 0 | K23: =J23+K22 -> 0 | ... N23: =M23+N22 -> 0 | P23: 10
A24: 산업용 | O24: =SUM(C24:N24) -> 0 | P24: 11
B25: (누계) | C25: =C24 -> 0 | D25: =C25+D24 -> 0 | E25: =D25+E24 -> 0 | F25: =E25+F24 -> 0 | G25: =F25+G24 -> 0 | H25: =G25+H24 -> 0 | I25: =H25+I24 -> 0 | J25: =I25+J24 -> 0 | K25: =J25+K24 -> 0 | ... N25: =M25+N24 -> 0 | P25: 12
A26: 열병합용 | O26: =SUM(C26:N26) -> 0 | P26: 13
B27: (누계) | C27: =C26 -> 0 | D27: =C27+D26 -> 0 | E27: =D27+E26 -> 0 | F27: =E27+F26 -> 0 | G27: =F27+G26 -> 0 | H27: =G27+H26 -> 0 | I27: =H27+I26 -> 0 | J27: =I27+J26 -> 0 | K27: =J27+K26 -> 0 | ... N27: =M27+N26 -> 0 | P27: 14
A28: 합 계 | C28: =SUM(C15,C17,C20,C22,C24,C26) -> 0 | D28: =SUM(D15,D17,D20,D22,D24,D26) -> 0 | E28: =SUM(E15,E17,E20,E22,E24,E26) -> 0 | F28: =SUM(F15,F17,F20,F22,F24,F26) -> 0 | G28: =SUM(G15,G17,G20,G22,G24,G26) -> 0 | H28: =SUM(H15,H17,H20,H22,H24,H26) -> 0 | I28: =SUM(I15,I17,I20,I22,I24,I26) -> 0 | J28: =SUM(J15,J17,J20,J22,J24,J26) -> 0 | ... N28: =SUM(N15,N17,N20,N22,N24,N26) -> 0 | O28: =SUM(C28:N28) -> 0 | P28: 15
B29: (누계) | C29: =C28 -> 0 | D29: =C29+D28 -> 0 | E29: =D29+E28 -> 0 | F29: =E29+F28 -> 0 | G29: =F29+G28 -> 0 | H29: =G29+H28 -> 0 | I29: =H29+I28 -> 0 | J29: =I29+J28 -> 0 | K29: =J29+K28 -> 0 | ... N29: =M29+N28 -> 0 | P29: 16
P30: 17
A31: 2. 공급량 실적 | P31: 18
A32: 구분 | C32: 1 | D32: 2 | E32: 3 | F32: 4 | G32: 5 | H32: 6 | I32: 7 | J32: 8 | K32: 9 | L32: 10 | M32: 11 | N32: 12 | O32: 비 고 | P32: 19
A33: 공급량 | B33: 열량(MJ) | P33: 20
B34: 부피(㎥) | P34: 21
B35: 환산값 | C35: =C33/C34 -> #DIV/0! | D35: =D33/D34 -> #DIV/0! | E35: =E33/E34 -> #DIV/0! | F35: =F33/F34 -> #DIV/0! | G35: =G33/G34 -> #DIV/0! | H35: =H33/H34 -> #DIV/0! | I35: =I33/I34 -> #DIV/0! | J35: =J33/J34 -> #DIV/0! | ... N35: =N33/N34 -> #DIV/0! | P35: 22
D36: =D33+C33 -> 0 | E36: =D36+E33 -> 0 | F36: =E36+F33 -> 0 | G36: =F36+G33 -> 0 | H36: =G36+H33 -> 0 | I36: =H36+I33 -> 0 | J36: =I36+J33 -> 0 | K36: =J36+K33 -> 0 | L36: =K36+L33 -> 0 | ... N36: =M36+N33 -> 0 | P36: 23
A37: 2. 신규개발량(㎥) | D37: =D34+C34 -> 0 | E37: =D37+E34 -> 0 | F37: =E37+F34 -> 0 | G37: =F37+G34 -> 0 | H37: =G37+H34 -> 0 | I37: =H37+I34 -> 0 | J37: =I37+J34 -> 0 | K37: =J37+K34 -> 0 | L37: =K37+L34 -> 0 | ... N37: =M37+N34 -> 0 | P37: 24
A38: 구분 | C38: 1 | D38: 2 | E38: 3 | F38: 4 | G38: 5 | H38: 6 | I38: 7 | J38: 8 | K38: 9 | L38: 10 | M38: 11 | N38: 12 | O38: 계 | P38: 25 | S38: 1
A39: 공동주택 | C39: =ROUND(C15*$R$39,0) -> 0 | D39: =ROUND(D15*$R$39,0) -> 0 | E39: =ROUND(E15*$R$39,0) -> 0 | F39: =ROUND(F15*$R$39,0) -> 0 | G39: =ROUND(G15*$R$39,0) -> 0 | H39: =ROUND(H15*$R$39,0) -> 0 | I39: =ROUND(I15*$R$39,0) -> 0 | J39: =ROUND(J15*$R$39,0) -> 0 | ... N39: =ROUND(N15*$R$39,0) -> 0 | O39: =SUM(C39:N39) -> 0 | P39: 26 | Q39: 공동주택 | R39: ='3_1. 개발량 계획'!R21 -> 47.4 | S39: 2
B40: (누계) | C40: =C39 -> 0 | D40: =C40+D39 -> 0 | E40: =D40+E39 -> 0 | F40: =E40+F39 -> 0 | G40: =F40+G39 -> 0 | H40: =G40+H39 -> 0 | I40: =H40+I39 -> 0 | J40: =I40+J39 -> 0 | K40: =J40+K39 -> 0 | ... N40: =M40+N39 -> 0 | O40: =SUM(C40:N40) -> 0 | P40: 27 | S40: 3
B41: (누적) | C41: =C40 -> 0 | D41: =C41+D40 -> 0 | E41: =D41+E40 -> 0 | F41: =E41+F40 -> 0 | G41: =F41+G40 -> 0 | H41: =G41+H40 -> 0 | I41: =H41+I40 -> 0 | J41: =I41+J40 -> 0 | K41: =J41+K40 -> 0 | ... N41: =M41+N40 -> 0 | O41: =EXACT(O40,N41) -> TRUE | P41: 28 | S41: 4
...

Sheet 영업용발췌(kpi관련)
A5: 구분 | C5: 1 | D5: 2 | E5: 3 | F5: 4 | G5: 5 | H5: 6 | I5: 7 | J5: 8 | K5: 9 | L5: 10 | M5: 11 | N5: 12 | O5: 계
A6: 일반용 | B6: 전수 | C6: 59 | D6: 84 | E6: 92 | F6: 65 | G6: 67 | H6: 77 | I6: 67 | J6: 79 | K6: 92 | L6: 71 | M6: 59 | N6: 83 | O6: =SUM(C6:N6) -> 895
B7: (누계) | C7: =C6 -> 59 | D7: =C7+D6 -> 143 | E7: =D7+E6 -> 235 | F7: =E7+F6 -> 300 | G7: =F7+G6 -> 367 | H7: =G7+H6 -> 444 | I7: =H7+I6 -> 511 | J7: =I7+J6 -> 590 | K7: =J7+K6 -> 682 | ... N7: =M7+N6 -> 895
A9: 일반용 | B9: 개발량 | C9: =ROUND(C6*$R$9,0) -> 6549 | D9: =ROUND(D6*$R$9,0) -> 9324 | E9: =ROUND(E6*$R$9,0) -> 10212 | F9: =ROUND(F6*$R$9,0) -> 7215 | G9: =ROUND(G6*$R$9,0) -> 7437 | H9: =ROUND(H6*$R$9,0) -> 8547 | I9: =ROUND(I6*$R$9,0) -> 7437 | J9: =ROUND(J6*$R$9,0) -> 8769 | ... N9: =ROUND(N6*$R$9,0) -> 9213 | O9: =SUM(C9:N9) -> 99345 | Q9: 일반용 | R9: 111
B10: (누계) | C10: =C9 -> 6549 | D10: =C10+D9 -> 15873 | E10: =D10+E9 -> 26085 | F10: =E10+F9 -> 33300 | G10: =F10+G9 -> 40737 | H10: =G10+H9 -> 49284 | I10: =H10+I9 -> 56721 | J10: =I10+J9 -> 65490 | K10: =J10+K9 -> 75702 | ... N10: =M10+N9 -> 99345 | O10: =SUM(C10:N10) -> 642801
B11: (누적) | C11: =C10 -> 6549 | D11: =C11+D10 -> 22422 | E11: =D11+E10 -> 48507 | F11: =E11+F10 -> 81807 | G11: =F11+G10 -> 122544 | H11: =G11+H10 -> 171828 | I11: =H11+I10 -> 228549 | J11: =I11+J10 -> 294039 | K11: =J11+K10 -> 369741 | ... N11: =M11+N10 -> 642801 | O11: =EXACT(O10,N11) -> TRUE
B14: 환산값 | C14: 42.981723 | D14: 43.088884 | E14: 43.068523 | F14: 42.931832 | G14: 42.572401 | H14: 42.552451 | I14: 42.675424 | J14: 42.53438 | K14: 42.4427 | L14: 42.611967 | M14: 42.673198 | N14: 42.569104
A17: ■ 중점추진업무 관련 신규개발량(다소비업종 실 신규개발량 + 월별 다소비업종 전수 제외한 전당사용량 적용 신규개발량)
A18: 구분 | C18: 1 | D18: 2 | E18: 3 | F18: 4 | G18: 5 | H18: 6 | I18: 7 | J18: 8 | K18: 9 | L18: 10 | M18: 11 | N18: 12 | O18: 계
A19: 일반용 | B19: 전수 | C19: =59-C31 -> 54 | D19: =84-D31 -> 80 | E19: =92-E31 -> 82 | F19: =65-F31 -> 49 | G19: =67-G31 -> 54 | H19: =77-H31 -> 62 | I19: =67-I31 -> 55 | J19: =79-J31 -> 62 | K19: =92-K31 -> 72 | L19: =71-L31 -> 60 | M19: =59-M31 -> 52 | N19: =83-N31 -> 80 | O19: =SUM(C19:N19) -> 762
B20: (누계) | C20: =C19 -> 54 | D20: =C20+D19 -> 134 | E20: =D20+E19 -> 216 | F20: =E20+F19 -> 265 | G20: =F20+G19 -> 319 | H20: =G20+H19 -> 381 | I20: =H20+I19 -> 436 | J20: =I20+J19 -> 498 | K20: =J20+K19 -> 570 | ... N20: =M20+N19 -> 762
A22: 일반용 (㎥) | C22: =ROUND(C19*$R$22,0) -> 5994 | D22: =ROUND(D19*$R$22,0) -> 8880 | E22: =ROUND(E19*$R$22,0) -> 9102 | F22: =ROUND(F19*$R$22,0) -> 5439 | G22: =ROUND(G19*$R$22,0) -> 5994 | H22: =ROUND(H19*$R$22,0) -> 6882 | I22: =ROUND(I19*$R$22,0) -> 6105 | J22: =ROUND(J19*$R$22,0) -> 6882 | ... N22: =ROUND(N19*$R$22,0) -> 8880 | O22: =SUM(C22:N22) -> 84582 | Q22: 일반용 | R22: 111
B23: (누계) | C23: =C22 -> 5994 | D23: =C23+D22 -> 14874 | E23: =D23+E22 -> 23976 | F23: =E23+F22 -> 29415 | G23: =F23+G22 -> 35409 | H23: =G23+H22 -> 42291 | I23: =H23+I22 -> 48396 | J23: =I23+J22 -> 55278 | K23: =J23+K22 -> 63270 | ... N23: =M23+N22 -> 84582 | O23: =SUM(C23:N23) -> 549117
B24: (누적) | C24: =C23 -> 5994 | D24: =C24+D23 -> 20868 | E24: =D24+E23 -> 44844 | F24: =E24+F23 -> 74259 | G24: =F24+G23 -> 109668 | H24: =G24+H23 -> 151959 | I24: =H24+I23 -> 200355 | J24: =I24+J23 -> 255633 | K24: =J24+K23 -> 318903 | ... N24: =M24+N23 -> 549117 | O24: =EXACT(O23,N24) -> TRUE
A25: 일반용 (MJ) | C25: =ROUND(C22*C14,0) -> 257632 | D25: =ROUND(D22*D14,0) -> 382629 | E25: =ROUND(E22*E14,0) -> 392010 | F25: =ROUND(F22*F14,0) -> 233506 | G25: =ROUND(G22*G14,0) -> 255179 | H25: =ROUND(H22*H14,0) -> 292846 | I25: =ROUND(I22*I14,0) -> 260533 | J25: =ROUND(J22*J14,0) -> 292722 | ... N25: =ROUND(N22*N14,0) -> 378014 | O25: =SUM(C25:N25) -> 3614379
B26: (누계) | C26: =C25 -> 257632 | D26: =C26+D25 -> 640261 | E26: =D26+E25 -> 1032271 | F26: =E26+F25 -> 1265777 | G26: =F26+G25 -> 1520956 | H26: =G26+H25 -> 1813802 | I26: =H26+I25 -> 2074335 | J26: =I26+J25 -> 2367057 | K26: =J26+K25 -> 2706259 | ... N26: =M26+N25 -> 3614379 | O26: =SUM(C26:N26) -> 23519149
B27: (누적) | C27: =C26 -> 257632 | D27: =C27+D26 -> 897893 | E27: =D27+E26 -> 1930164 | F27: =E27+F26 -> 3195941 | G27: =F27+G26 -> 4716897 | H27: =G27+H26 -> 6530699 | I27: =H27+I26 -> 8605034 | J27: =I27+J26 -> 10972091 | K27: =J27+K26 -> 13678350 | ... N27: =M27+N26 -> 23519149 | O27: =EXACT(O26,N27) -> TRUE
A29: ---- 다소비 업종 신규개발량(김상욱 부팀장님 관리 자료 적용)
A30: 구분 | C30: 1 | D30: 2 | E30: 3 | F30: 4 | G30: 5 | H30: 6 | I30: 7 | J30: 8 | K30: 9 | L30: 10 | M30: 11 | N30: 12 | O30: 계
A31: 일반용 | B31: 전수 | C31: 5 | D31: 4 | E31: 10 | F31: 16 | G31: 13 | H31: 15 | I31: 12 | J31: 17 | K31: 20 | L31: 11 | M31: 7 | N31: 3 | O31: =SUM(C31:N31) -> 133 | Q31: D:\수요개발팀\기획\000. 월별 실적_매월 확인_추정\2. 신규 개발량\2023년\2023년 다소비업종 신규개발량 실적 입력
B32: (누계) | C32: =C31 -> 5 | D32: =C32+D31 -> 9 | E32: =D32+E31 -> 19 | F32: =E32+F31 -> 35 | G32: =F32+G31 -> 48 | H32: =G32+H31 -> 63 | I32: =H32+I31 -> 75 | J32: =I32+J31 -> 92 | K32: =J32+K31 -> 112 | ... N32: =M32+N31 -> 133
A34: 일반용 (㎥) | B34: 개발량 | C34: 1408.3431 | D34: 2946.3369 | E34: 7509.8436 | F34: 13912.213 | G34: 23036.257 | H34: 30195.337 | I34: 33151.665 | J34: 35657.055 | K34: 42786.488 | L34: 45476.84 | M34: 54709.099 | N34: 62991.823 | O34: =SUM(C34:N34) -> 353781.3
B35: (누계)
B36: (누적)
A38: 일반용(MJ) | B38: 개발량 | C38: 60527.793 | D38: 126599.48 | E38: 323826.12 | F38: 598936.5 | G38: 988157.76 | H38: 1284795.8 | I38: 1411474.6 | J38: 1521657.3 | K38: 1818856.4 | L38: 1930189.1 | M38: 2332766.4 | N38: 2685453.7 | O38: =SUM(C38:N38) -> 15083241 | Q38: D:\수요개발팀\기획\000. 월별 실적_매월 확인_추정\2. 신규 개발량\2023년\2023년 다소비업종 신규개발량 실적 입력
A40: 일반용 신규개발량(㎥) | C40: =C23+C34 -> 7402.3431 | D40: =D23+D34 -> 17820.337 | E40: =E23+E34 -> 31485.844 | F40: =F23+F34 -> 43327.213 | G40: =G23+G34 -> 58445.257 | H40: =H23+H34 -> 72486.337 | I40: =I23+I34 -> 81547.665 | J40: =J23+J34 -> 90935.055 | ... N40: =N23+N34 -> 147573.82 | O40: =SUM(C40:N40) -> 902898.3 | Q40: =O40/Q45 -> 1.0788089
A42: 일반용 신규개발량(MJ) | C42: =C26+C38 -> 318159.79 | D42: =D26+D38 -> 766860.48 | E42: =E26+E38 -> 1356097.1 | F42: =F26+F38 -> 1864713.5 | G42: =G26+G38 -> 2509113.8 | H42: =H26+H38 -> 3098597.8 | I42: =I26+I38 -> 3485809.6 | J42: =J26+J38 -> 3888714.3 | ... N42: =N26+N38 -> 6299832.7 | O42: =SUM(C42:N42) -> 38602390
A45: 일반용 | B45: 개발량 | C45: 626.4801 | D45: 11767.533 | E45: 24690.046 | F45: 45890.41 | G45: 64250.334 | H45: 80425.93 | I45: 95966.386 | J45: 104759.54 | K45: 117263.74 | L45: 131130.92 | M45: 148248.29 | N45: 169614.82 | O45: =SUM(C45:N45) -> 994634.43 | Q45: 836940
B46: (누계) | Q46: =O45/Q45 -> 1.1884178
B47: (누적)
B50: 열량
A51: 공동 | B51: 544269 | C51: 477510 | D51: =C51/B51 -> 0.8773419
A52: 단독 | B52: 61234 | C52: 37017 | D52: =C52/B52 -> 0.6045171
A53: 가정용 | B53: 605503 | C53: 514527 | D53: =C53/B53 -> 0.84975136
A54: 영업용 | B54: 35695 | C54: 23519 | D54: =SUM(C54:C55)/B54 -> 1.0812159
C55: 15075
B56: 35695 | C56: 38594 | D56: =C56/B56 -> 1.0812159
B57: =B56+B53 -> 641198 | C57: =C56+C53 -> 553121 | D57: =C57/B57 -> 0.86263681
A59: 업무 | B59: 56955 | C59: 59421 | D59: =C59/B59 -> 1.0432973
A60: 산업 | B60: 34256 | C60: 38454 | D60: =C60/B60 -> 1.1225479
...

Sheet 4_1. 공급전 계획
A1: 2025년 개발 계획
A2: 1. 공급전 | B2: ▶ 당초사업계획 → [공급전계획 sheet]
A3: 구 분 | B3: 상 반 기 | H3: 하 반 기 | N3: 연간계
B4: 1 | C4: 2 | D4: 3 | E4: 4 | F4: 5 | G4: 6 | H4: 7 | I4: 8 | J4: 9 | K4: 10 | L4: 11 | M4: 12
A5: 공동주택 | B5: ='3_1. 개발량 계획'!C3 -> 2514 | C5: ='3_1. 개발량 계획'!D3 -> 1896 | D5: ='3_1. 개발량 계획'!E3 -> 1311 | E5: ='3_1. 개발량 계획'!F3 -> 913 | F5: ='3_1. 개발량 계획'!G3 -> 1180 | G5: ='3_1. 개발량 계획'!H3 -> 1298 | H5: ='3_1. 개발량 계획'!I3 -> 1130 | I5: ='3_1. 개발량 계획'!J3 -> 1397 | ... M5: ='3_1. 개발량 계획'!N3 -> 1197 | N5: =SUM(B5:M5) -> 16722 | P5: 매년 업데이트 | S5: =SUM(B5:G5) -> 9112
A6: 단독주택 | B6: ='3_1. 개발량 계획'!C5 -> 281 | C6: ='3_1. 개발량 계획'!D5 -> 196 | D6: ='3_1. 개발량 계획'!E5 -> 153 | E6: ='3_1. 개발량 계획'!F5 -> 152 | F6: ='3_1. 개발량 계획'!G5 -> 145 | G6: ='3_1. 개발량 계획'!H5 -> 153 | H6: ='3_1. 개발량 계획'!I5 -> 179 | I6: ='3_1. 개발량 계획'!J5 -> 170 | ... M6: ='3_1. 개발량 계획'!N5 -> 304 | N6: =SUM(B6:M6) -> 2372 | S6: =SUM(B6:G6) -> 1080
A7: 가정용 | B7: =SUM(B5:B6) -> 2795 | C7: =SUM(C5:C6) -> 2092 | D7: =SUM(D5:D6) -> 1464 | E7: =SUM(E5:E6) -> 1065 | F7: =SUM(F5:F6) -> 1325 | G7: =SUM(G5:G6) -> 1451 | H7: =SUM(H5:H6) -> 1309 | I7: =SUM(I5:I6) -> 1567 | ... M7: =SUM(M5:M6) -> 1501 | N7: =SUM(B7:M7) -> 19094 | S7: =SUM(B7:G7) -> 10192
A8: 일반용 | B8: ='3_1. 개발량 계획'!C8 -> 66 | C8: ='3_1. 개발량 계획'!D8 -> 57 | D8: ='3_1. 개발량 계획'!E8 -> 71 | E8: ='3_1. 개발량 계획'!F8 -> 72 | F8: ='3_1. 개발량 계획'!G8 -> 72 | G8: ='3_1. 개발량 계획'!H8 -> 67 | H8: ='3_1. 개발량 계획'!I8 -> 70 | I8: ='3_1. 개발량 계획'!J8 -> 65 | ... M8: ='3_1. 개발량 계획'!N8 -> 90 | N8: =SUM(B8:M8) -> 868 | S8: =SUM(B8:G8) -> 405
A9: 업무용 | B9: ='3_1. 개발량 계획'!C10 -> 31 | C9: ='3_1. 개발량 계획'!D10 -> 24 | D9: ='3_1. 개발량 계획'!E10 -> 27 | E9: ='3_1. 개발량 계획'!F10 -> 33 | F9: ='3_1. 개발량 계획'!G10 -> 25 | G9: ='3_1. 개발량 계획'!H10 -> 22 | H9: ='3_1. 개발량 계획'!I10 -> 23 | I9: ='3_1. 개발량 계획'!J10 -> 27 | ... M9: ='3_1. 개발량 계획'!N10 -> 30 | N9: =SUM(B9:M9) -> 313 | S9: =SUM(B9:G9) -> 162
A10: 산업용 | B10: ='3_1. 개발량 계획'!C12 -> 1 | C10: ='3_1. 개발량 계획'!D12 -> 1 | D10: ='3_1. 개발량 계획'!E12 -> 0 | E10: ='3_1. 개발량 계획'!F12 -> 1 | F10: ='3_1. 개발량 계획'!G12 -> 1 | G10: ='3_1. 개발량 계획'!H12 -> 1 | H10: ='3_1. 개발량 계획'!I12 -> 0 | I10: ='3_1. 개발량 계획'!J12 -> 1 | ... M10: ='3_1. 개발량 계획'!N12 -> 2 | N10: =SUM(B10:M10) -> 12 | S10: =SUM(B10:G10) -> 5
A11: 열병합용 | B11: ='3_1. 개발량 계획'!C14 -> 0 | C11: ='3_1. 개발량 계획'!D14 -> 0 | D11: ='3_1. 개발량 계획'!E14 -> 0 | E11: ='3_1. 개발량 계획'!F14 -> 1 | F11: ='3_1. 개발량 계획'!G14 -> 0 | G11: ='3_1. 개발량 계획'!H14 -> 0 | H11: ='3_1. 개발량 계획'!I14 -> 4 | I11: ='3_1. 개발량 계획'!J14 -> 1 | ... M11: ='3_1. 개발량 계획'!N14 -> 1 | N11: =SUM(B11:M11) -> 7 | S11: =SUM(B11:G11) -> 1
A12: 합 계 | B12: =SUM(B7:B11) -> 2893 | C12: =SUM(C7:C11) -> 2174 | D12: =SUM(D7:D11) -> 1562 | E12: =SUM(E7:E11) -> 1172 | F12: =SUM(F7:F11) -> 1423 | G12: =SUM(G7:G11) -> 1541 | H12: =SUM(H7:H11) -> 1406 | I12: =SUM(I7:I11) -> 1661 | ... M12: =SUM(M7:M11) -> 1624 | N12: =SUM(B12:M12) -> 20294 | S12: =SUM(B12:G12) -> 10765
A14: 2. 개발량(㎥)
A15: 구 분 | B15: 상 반 기 | H15: 하 반 기 | N15: 연간계
B16: 1 | C16: 2 | D16: 3 | E16: 4 | F16: 5 | G16: 6 | H16: 7 | I16: 8 | J16: 9 | K16: 10 | L16: 11 | M16: 12
A17: 공동주택 | B17: ='3_1. 개발량 계획'!C21 -> 119164 | C17: ='3_1. 개발량 계획'!D21 -> 89870 | D17: ='3_1. 개발량 계획'!E21 -> 62141 | E17: ='3_1. 개발량 계획'!F21 -> 43276 | F17: ='3_1. 개발량 계획'!G21 -> 55932 | G17: ='3_1. 개발량 계획'!H21 -> 61525 | H17: ='3_1. 개발량 계획'!I21 -> 53562 | I17: ='3_1. 개발량 계획'!J21 -> 66218 | ... M17: ='3_1. 개발량 계획'!N21 -> 56738 | N17: =SUM(B17:M17) -> 792622
A18: 단독주택 | B18: ='3_1. 개발량 계획'!C24 -> 11746 | C18: ='3_1. 개발량 계획'!D24 -> 8193 | D18: ='3_1. 개발량 계획'!E24 -> 6395 | E18: ='3_1. 개발량 계획'!F24 -> 6354 | F18: ='3_1. 개발량 계획'!G24 -> 6061 | G18: ='3_1. 개발량 계획'!H24 -> 6395 | H18: ='3_1. 개발량 계획'!I24 -> 7482 | I18: ='3_1. 개발량 계획'!J24 -> 7106 | ... M18: ='3_1. 개발량 계획'!N24 -> 12707 | N18: =SUM(B18:M18) -> 99149
A19: 가정용 | B19: =SUM(B17:B18) -> 130910 | C19: =SUM(C17:C18) -> 98063 | D19: =SUM(D17:D18) -> 68536 | E19: =SUM(E17:E18) -> 49630 | F19: =SUM(F17:F18) -> 61993 | G19: =SUM(G17:G18) -> 67920 | H19: =SUM(H17:H18) -> 61044 | I19: =SUM(I17:I18) -> 73324 | ... M19: =SUM(M17:M18) -> 69445 | N19: =SUM(B19:M19) -> 891771
A20: 일반용 | B20: ='3_1. 개발량 계획'!C30 -> 13233 | C20: ='3_1. 개발량 계획'!D30 -> 11429 | D20: ='3_1. 개발량 계획'!E30 -> 14236 | E20: ='3_1. 개발량 계획'!F30 -> 14436 | F20: ='3_1. 개발량 계획'!G30 -> 14436 | G20: ='3_1. 개발량 계획'!H30 -> 13434 | H20: ='3_1. 개발량 계획'!I30 -> 14035 | I20: ='3_1. 개발량 계획'!J30 -> 13033 | ... M20: ='3_1. 개발량 계획'!N30 -> 18045 | N20: =SUM(B20:M20) -> 174037
A21: 업무용 | B21: ='3_1. 개발량 계획'!C33 -> 12720 | C21: ='3_1. 개발량 계획'!D33 -> 14061 | D21: ='3_1. 개발량 계획'!E33 -> 14748 | E21: ='3_1. 개발량 계획'!F33 -> 18134 | F21: ='3_1. 개발량 계획'!G33 -> 15552 | G21: ='3_1. 개발량 계획'!H33 -> 9691 | H21: ='3_1. 개발량 계획'!I33 -> 13799 | I21: ='3_1. 개발량 계획'!J33 -> 20789 | ... M21: ='3_1. 개발량 계획'!N33 -> 20189 | N21: =SUM(B21:M21) -> 183397
A22: 산업용 | B22: ='3_1. 개발량 계획'!C36 -> 5000 | C22: ='3_1. 개발량 계획'!D36 -> 20000 | D22: ='3_1. 개발량 계획'!E36 -> 0 | E22: ='3_1. 개발량 계획'!F36 -> 5000 | F22: ='3_1. 개발량 계획'!G36 -> 5000 | G22: ='3_1. 개발량 계획'!H36 -> 5000 | H22: ='3_1. 개발량 계획'!I36 -> 0 | I22: ='3_1. 개발량 계획'!J36 -> 5000 | ... M22: ='3_1. 개발량 계획'!N36 -> 10000 | N22: =SUM(B22:M22) -> 105000
A23: 열병합용 | B23: ='3_1. 개발량 계획'!C39 -> 0 | C23: ='3_1. 개발량 계획'!D39 -> 0 | D23: ='3_1. 개발량 계획'!E39 -> 0 | E23: ='3_1. 개발량 계획'!F39 -> 0 | F23: ='3_1. 개발량 계획'!G39 -> 0 | G23: ='3_1. 개발량 계획'!H39 -> 0 | H23: ='3_1. 개발량 계획'!I39 -> 0 | I23: ='3_1. 개발량 계획'!J39 -> 0 | ... M23: ='3_1. 개발량 계획'!N39 -> 0 | N23: =SUM(B23:M23) -> 0
A24: 합 계 | B24: =SUM(B19:B23) -> 161863 | C24: =SUM(C19:C23) -> 143553 | D24: =SUM(D19:D23) -> 97520 | E24: =SUM(E19:E23) -> 87200 | F24: =SUM(F19:F23) -> 96981 | G24: =SUM(G19:G23) -> 96045 | H24: =SUM(H19:H23) -> 88878 | I24: =SUM(I19:I23) -> 112146 | ... M24: =SUM(M19:M23) -> 117679 | N24: =SUM(B24:M24) -> 1354205
A26: 3. CNG | B26: ▶ 당초사업계획 → [CNG계획 sheet] → 신규도입대수
A27: 구 분 | B27: 상 반 기 | H27: 하 반 기 | N27: 연간계
B28: 1 | C28: 2 | D28: 3 | E28: 4 | F28: 5 | G28: 6 | H28: 7 | I28: 8 | J28: 9 | K28: 10 | L28: 11 | M28: 12
A29: 시내버스 | N29: =SUM(B29:M29) -> 0
A30: 버스(기타) | N30: =SUM(B30:M30) -> 0
A31: 청소차 | N31: =SUM(B31:M31) -> 0
A32: 택시 | N32: =SUM(B32:M32) -> 0
A33: 승용차 | N33: =SUM(B33:M33) -> 0
A34: 합 계 | B34: =SUM(B29:B33) -> 0 | C34: =SUM(C29:C33) -> 0 | D34: =SUM(D29:D33) -> 0 | E34: =SUM(E29:E33) -> 0 | F34: =SUM(F29:F33) -> 0 | G34: =SUM(G29:G33) -> 0 | H34: =SUM(H29:H33) -> 0 | I34: =SUM(I29:I33) -> 0 | ... M34: =SUM(M29:M33) -> 0 | N34: =SUM(B34:M34) -> 0

Sheet 4_2. 계약전 계획
A1: 2025년 계약전 계획
A2: 1. 계약전
A3: 구 분 | B3: 상 반 기 | H3: 하 반 기 | N3: 연간계
B4: 1 | C4: 2 | D4: 3 | E4: 4 | F4: 5 | G4: 6 | H4: 7 | I4: 8 | J4: 9 | K4: 10 | L4: 11 | M4: 12
A5: 공동주택 | B5: 1582 | C5: 3710 | D5: 368 | E5: 2341 | F5: 4831 | G5: 2381 | H5: 984 | I5: 593 | J5: 2082 | K5: 945 | L5: 117 | M5: 2993 | N5: =SUM(B5:M5) -> 22927 | P5: 매년 업데이트
A6: 단독주택 | B6: 96 | C6: 123 | D6: 121 | E6: 154 | F6: 256 | G6: 144 | H6: 182 | I6: 165 | J6: 761 | K6: 251 | L6: 246 | M6: 161 | N6: =SUM(B6:M6) -> 2660
A7: 가정용 | B7: =SUM(B5:B6) -> 1678 | C7: =SUM(C5:C6) -> 3833 | D7: =SUM(D5:D6) -> 489 | E7: =SUM(E5:E6) -> 2495 | F7: =SUM(F5:F6) -> 5087 | G7: =SUM(G5:G6) -> 2525 | H7: =SUM(H5:H6) -> 1166 | I7: =SUM(I5:I6) -> 758 | ... M7: =SUM(M5:M6) -> 3154 | N7: =SUM(B7:M7) -> 25587
A8: 일반용 | B8: 72 | C8: 45 | D8: 99 | E8: 73 | F8: 78 | G8: 63 | H8: 64 | I8: 76 | J8: 70 | K8: 77 | L8: 86 | M8: 97 | N8: =SUM(B8:M8) -> 900
A9: 업무용 | B9: 27 | C9: 22 | D9: 18 | E9: 36 | F9: 26 | G9: 34 | H9: 19 | I9: 20 | J9: 21 | K9: 33 | L9: 35 | M9: 26 | N9: =SUM(B9:M9) -> 317
A10: 산업용 | B10: 1 | C10: 4 | D10: 0 | E10: 1 | F10: 0 | G10: 0 | H10: 1 | I10: 1 | J10: 8 | K10: 0 | L10: 0 | M10: 0 | N10: =SUM(B10:M10) -> 16
A11: 열병합용 | B11: 0 | C11: 0 | D11: 0 | E11: 1 | F11: 0 | J11: 0 | K11: 1 | L11: 0 | M11: 0 | N11: =SUM(B11:M11) -> 2
A12: 합 계 | B12: =SUM(B7:B11) -> 1778 | C12: =SUM(C7:C11) -> 3904 | D12: =SUM(D7:D11) -> 606 | E12: =SUM(E7:E11) -> 2606 | F12: =SUM(F7:F11) -> 5191 | G12: =SUM(G7:G11) -> 2622 | H12: =SUM(H7:H11) -> 1250 | I12: =SUM(I7:I11) -> 855 | ... M12: =SUM(M7:M11) -> 3277 | N12: =SUM(B12:M12) -> 26822

Sheet 4_3. 일반용 판매량(2024년)
A1: 2024년 일반용 공급 계획
R2: (단위: ㎥)
A3: 구 분 | D3: 1월 | E3: 2월 | F3: 3월 | G3: 4월 | H3: 5월 | I3: 6월 | J3: 상반기계 | K3: 7월 | L3: 8월 | M3: 9월 | N3: 10월 | O3: 11월 | P3: 12월 | Q3: 하반기계 | R3: 년간계
A4: 공급일수 (조업일수) | B4: 사업계획 적용 일수 | D4: 29.5 | E4: 27.3 | F4: 29.2 | G4: 28.5 | H4: 29.4 | I4: 28.2 | K4: 29.7 | L4: 29.4 | M4: 27.2 | N4: 29.4 | O4: 28.6 | P4: 29.3
B5: 정수화 | D5: =ROUND(D4,0) -> 30 | E5: =ROUND(E4,0) -> 27 | F5: =ROUND(F4,0) -> 29 | G5: =ROUND(G4,0) -> 29 | H5: =ROUND(H4,0) -> 29 | I5: =ROUND(I4,0) -> 28 | J5: =SUM(D5:I5) -> 172 | K5: =ROUND(K4,0) -> 30 | L5: =ROUND(L4,0) -> 29 | M5: =ROUND(M4,0) -> 27 | N5: =ROUND(N4,0) -> 29 | O5: =ROUND(O4,0) -> 29 | P5: =ROUND(P4,0) -> 29 | Q5: =SUM(K5:P5) -> 173 | R5: =J5+Q5 -> 345
A6: 일반용 | B6: 일반용1 (영업) | C6: 공급업소수(전) | D6: 27099 | E6: 27154 | F6: 27222 | G6: 27290 | H6: 27358 | I6: 27418 | K6: 27482 | L6: 27544 | M6: 27610 | N6: 27690 | O6: 27784 | P6: 27878
C7: 평균공급업소수(전) | D7: 27067 | E7: 27099 | F7: 27154 | G7: 27222 | H7: 27290 | I7: 27358 | K7: 27418 | L7: 27482 | M7: 27544 | N7: 27610 | O7: 27690 | P7: 27784
C8: 업소당일공급량(MJ) | D8: 191.74402 | E8: 185.65042 | F8: 168.53238 | G8: 163.17562 | H8: 157.12953 | I8: 156.08485 | K8: 149.63117 | L8: 147.19763 | M8: 167.8088 | N8: 181.5204 | O8: 206.85283 | P8: 218.71966
C9: 업소당일공급량(㎥) | D9: =D10/D7/D5 -> 4.4202498 | E9: =E10/E7/E5 -> 4.4043965 | F9: =F10/F7/F5 -> 3.9835066 | G9: =G10/G7/G5 -> 3.7644084 | H9: =H10/H7/H5 -> 3.7393753 | I9: =I10/I7/I5 -> 3.6890489 | J9: =AVERAGE(D9:I9) -> 4.0001642 | K9: =K10/K7/K5 -> 3.4768096 | L9: =L10/L7/L5 -> 3.502192 | M9: =M10/M7/M5 -> 3.9679879 | N9: =N10/N7/N5 -> 4.3215789 | O9: =O10/O7/O5 -> 4.7930549 | P9: =P10/P7/P5 -> 5.1920083 | Q9: =AVERAGE(K9:P9) -> 4.2089386
C10: 월공급량(㎥/월) | D10: 3589287 | E10: 3222578 | F10: 3136876 | G10: 2971767 | H10: 2959379 | I10: 2825900 | J10: =SUM(D10:I10) -> 18705787 | K10: 2859815 | L10: 2791170 | M10: 2950945 | N10: 3460245 | O10: 3848871 | P10: 4183388 | Q10: =SUM(K10:P10) -> 20094434 | R10: =J10+Q10 -> 38800221
C11: 월공급량(GJ/월)
D13: 1월 | E13: 2월 | F13: 3월 | G13: 4월 | H13: 5월 | I13: 6월 | K13: 7월 | L13: 8월 | M13: 9월 | N13: 10월 | O13: 11월 | P13: 12월 | Q13: 전당사용량
C14: 평균전당사용량(㎥/전) | D14: =ROUND(D10/D7,0) -> 133 | E14: =ROUND(E10/E7,0) -> 119 | F14: =ROUND(F10/F7,0) -> 116 | G14: =ROUND(G10/G7,0) -> 109 | H14: =ROUND(H10/H7,0) -> 108 | I14: =ROUND(I10/I7,0) -> 103 | K14: =ROUND(K10/K7,0) -> 104 | L14: =ROUND(L10/L7,0) -> 102 | M14: =ROUND(M10/M7,0) -> 107 | N14: =ROUND(N10/N7,0) -> 125 | O14: =ROUND(O10/O7,0) -> 139 | P14: =ROUND(P10/P7,0) -> 151 | Q14: =ROUND(AVERAGE(D14:I14,K14:P14),0) -> 118
C16: ▶ 사업계획 적용 일수 : 해당년도 당초 사업계획 → [공급량계획 sheet] → 당년 조업일수 입력
C17: ▶ 정수화 : round 함수
C18: ▶ 일반용1(영업) : 해당년도 당초 사업계획 → [공급량계획 sheet] → 28행~ 입력

Sheet 5. 업무용 판매량(2025년)
A1: 2025년 업무용 공급 계획
R2: (단위: MJ) | S2: 2025년 열량값 | T2: 42.369
A3: NO | B3: 공급대상 | C3: 월 | D3: 1월 | E3: 2월 | F3: 3월 | G3: 4월 | H3: 5월 | I3: 6월 | J3: 상반기계 | K3: 7월 | L3: 8월 | M3: 9월 | N3: 10월 | O3: 11월 | P3: 12월 | Q3: 하반기계 | R3: 년간계
A4: =ROW()-3 -> 1 | B4: 일반용1 | C4: 1 | D4: 148479 | E4: 148479 | F4: 148479 | G4: 148479 | H4: 148479 | I4: 148479 | J4: 890874 | K4: 148479 | L4: 148479 | M4: 148479 | N4: 148479 | O4: 148479 | P4: 148479 | Q4: 890874 | R4: 1781748
A5: =ROW()-3 -> 2 | B5: 일반용2 | C5: 1 | D5: 143229 | E5: 143229 | F5: 143229 | G5: 143229 | H5: 143229 | I5: 143229 | J5: 859374 | K5: 143229 | L5: 143229 | M5: 143229 | N5: 143229 | O5: 143229 | P5: 143229 | Q5: 859374 | R5: 1718748
A6: =ROW()-3 -> 3 | B6: 업무난방용 | C6: 1 | D6: 177735 | E6: 177735 | F6: 177735 | G6: 177735 | H6: 177735 | I6: 177735 | J6: 1066410 | K6: 177735 | L6: 177735 | M6: 177735 | N6: 177735 | O6: 177735 | P6: 177735 | Q6: 1066410 | R6: 2132820
A7: =ROW()-3 -> 4 | B7: 냉난방용 | C7: 1 | D7: 69477 | E7: 69477 | F7: 69477 | G7: 69477 | H7: 69477 | I7: 69477 | J7: 416862 | K7: 69477 | L7: 69477 | M7: 69477 | N7: 69477 | O7: 69477 | P7: 69477 | Q7: 416862 | R7: 833724
A8: =ROW()-3 -> 5 | B8: 주한미군 | C8: 1 | D8: 0 | E8: 0 | F8: 0 | G8: 0 | H8: 0 | I8: 0 | J8: 0 | K8: 0 | L8: 0 | M8: 0 | N8: 0 | O8: 0 | P8: 0 | Q8: 0 | R8: 0
A9: =ROW()-3 -> 6 | B9: 일반용1 | C9: 2 | E9: 174475 | F9: 174475 | G9: 174475 | H9: 174475 | I9: 174475 | J9: 872375 | K9: 174475 | L9: 174475 | M9: 174475 | N9: 174475 | O9: 174475 | P9: 174475 | Q9: 1046850 | R9: 1919225
A10: =ROW()-3 -> 7 | B10: 일반용2 | C10: 2 | E10: 170749 | F10: 170749 | G10: 170749 | H10: 170749 | I10: 170749 | J10: 853745 | K10: 170749 | L10: 170749 | M10: 170749 | N10: 170749 | O10: 170749 | P10: 170749 | Q10: 1024494 | R10: 1878239
A11: =ROW()-3 -> 8 | B11: 업무난방용 | C11: 2 | E11: 108893 | F11: 108893 | G11: 108893 | H11: 108893 | I11: 108893 | J11: 544465 | K11: 108893 | L11: 108893 | M11: 108893 | N11: 108893 | O11: 108893 | P11: 108893 | Q11: 653358 | R11: 1197823
